Workbook

Sheet Lead Time
A1: Article | B1: Désignation article | C1: Local /Import | D1: Lead Time (Days)
A2: 83520000 | B2: Achat Consommables Industriel | C2: Mixed Source | D2: 109.33758
A3: 76210012 | B3: Rouleau doseur 61x1350mm | C3: Import | D3: 283.2
A4: 86100028 | B4: VIS CONE MOBILE M52X300 L639 TH | C4: Local | D4: 15.8
A5: 78610122 | B5: VERIN P1D S050 MC 0050-B201211/09/36 | C5: Mixed Source | D5: 79.160714
A6: 78610119 | B6: VERIN P1D SO50-MC0145 B201444-08-48 | C6: Mixed Source | D6: 93.428571
A7: 02020007 | B7: Pet Coke Broyé (HS) | D7: 44
A8: 59600055 | B8: ELECTROVANNE HT 230V ALTERNATIF AIR CHOC | C8: Import | D8: 74.5
A9: 04030001 | B9: Pet Coke Brut (MS) | C9: Import | D9: 17.960784
A10: 71030061 | B10: Bande NHM-10ESBV 2190*600 EP : 03mm | C10: Local | D10: 19.466667
A11: 65660006 | B11: GALET COMPLET Ø108+AXE (KZB250-800X300X4 | C11: Mixed Source | D11: 53.8
A12: 45600027 | B12: Acide pour détartrage Treatonet DDB044 | C12: Local | D12: 13.583333
A13: 78610111 | B13: VERIN PID S040 MC 0100 B201215 R:640466Z | C13: Mixed Source | D13: 42.002717
A14: 78610124 | B14: VERIN 241Z25B040XP M.WORK ref:641802D | C14: Local | D14: 18.666667
A15: 40010001 | B15: CHARGE ACYTELENE ALTOP | C15: Local | D15: 14.62069
A16: 90250052 | B16: BUSE RINGARDAGE REF:REF B33*1,5 | C16: Local | D16: 36.666667
A17: 83300018 | B17: FILTRE HUILE COMP DSD238 RÉF 6.3465.0 | C17: Local | D17: 11.363636
A18: 43200054 | B18: Electrode OK 67.45 E307 3.2mm | C18: Local | D18: 13.125
A19: 59050017 | B19: DETECTEUR *IGM200 | C19: Local | D19: 86.2
... A35: 91100459 | B35: SELLE DROITE | C35: Local | D35: 171.5
A36: 02030003 | B36: CEMI HRS SAC | D36: 44
A37: 53250184 | B37: Relais thermique 23-32A LRD332 | C37: Local | D37: 99
A38: 10030103 | B38: BRIQUE MLA RP201 KROSAKI | D38: 0
A39: 20300015 | B39: FER PLAT 100*8 LONG 6M | C39: Local | D39: 36
A40: 20030006 | B40: POUTREL EN ACIER UPN80 (6m) | C40: Local | D40: 17.9
A41: 83300017 | B41: FILTRE HUILE COMP ASD57 REF 6.3463.0 | C41: Local | D41: 58.75
A42: 84100979 | B42: Cale 1 (100*100) TMAS 100-100 | C42: Local | D42: 76
A43: 90250019 | B43: RONDELLE BASSE rep1268 | C43: Mixed Source | D43: 25.846154
A44: 20010002 | B44: POUTRE IPN 100 6M | C44: Local | D44: 12.2
A45: 02030001 | B45: CEMI 42.5 SAC | D45: 44
A46: 39210008 | B46: JOINT TORIQUE VITON D164,77 | C46: Import | D46: 53
A47: 72170015 | B47: GYROPHARE COMPLET 24V pour CLARK 7T | C47: Local | D47: 9.5
A48: 91300015 | B48: AXE COMMANDE AIGUILLEUR SAC | C48: Local | D48: 38.4
A49: 53130130 | B49: CONTACTEUR TRIPOLAIRE LC1D09BD. 24VCC | C49: Local | D49: 43.666667
A50: 71240012 | B50: Rouleaux retour Ø89/133x950 A2 axe Ø25 | C50: Local | D50: 126
A51: 65200148 | B51: Palier COMPLET SYJ 40 TF ..(SYJ508 )SKF | C51: Local | D51: 34.2
A52: 43200016 | B52: BAGUETTE INOX DIAM 2,5mm 24/12 | C52: Local | D52: 14.625
A53: 60570003 | B53: DETECT. ROXIMITÉ IND. XS1 18BLPAM12 SCHN | C53: Local | D53: 121.66667
A54: 37230003 | B54: G_ind 92 /KLUBER:Graflscon C-SG 0 ultra | C54: Local | D54: 32
A55: 90250020 | B55: RONDELLE EN BRONZE rep1257 | C55: Local | D55: 9.9285714
...

Sheet Consumption
A1: Article | B1: Désignation article | C1: Unit | D1: Month | E1: Valeur
A2: 83520000 | B2: Achat Consommables Industriel | C2: PC | D2: janv-23 | E2: 0
A3: 83520000 | B3: Achat Consommables Industriel | C3: PC | D3: févr-23 | E3: 0
A4: 83520000 | B4: Achat Consommables Industriel | C4: PC | D4: mars-23 | E4: 0
A5: 83520000 | B5: Achat Consommables Industriel | C5: PC | D5: avr-23 | E5: 0
A6: 83520000 | B6: Achat Consommables Industriel | C6: PC | D6: mai-23 | E6: 0
A7: 83520000 | B7: Achat Consommables Industriel | C7: PC | D7: juin-23 | E7: 0
A8: 83520000 | B8: Achat Consommables Industriel | C8: PC | D8: juil-23 | E8: 0
A9: 83520000 | B9: Achat Consommables Industriel | C9: PC | D9: août-23 | E9: 0
A10: 83520000 | B10: Achat Consommables Industriel | C10: PC | D10: sept-23 | E10: 0
A11: 83520000 | B11: Achat Consommables Industriel | C11: PC | D11: oct-23 | E11: 0
A12: 83520000 | B12: Achat Consommables Industriel | C12: PC | D12: nov-23 | E12: 0
A13: 83520000 | B13: Achat Consommables Industriel | C13: PC | D13: déc-23 | E13: 0
... A42445: 30090006 | B42445: CHEVILLE PLASTIQUE 6 MM | C42445: PC | D42445: déc-25 | E42445: 0

Sheet cons 2023 - 2025
D2: 2023 | P2: 2024 | AB2: 2025
A3: Article | B3: Désignation article | C3: Unit | D3: 44927 | E3: 44958 | F3: 44986 | G3: 45017 | H3: 45047 | I3: 45078 | J3: 45108 | K3: 45139 | L3: 45170 | M3: 45200 | N3: 45231 | O3: 45261 | P3: 45292 | Q3: 45323 | R3: 45352 | S3: 45383 | T3: 45413 | U3: 45444 | V3: 45474 | W3: 45505 | X3: 45536 | Y3: 45566 | Z3: 45597 | AA3: 45627 | AB3: 45658 | AC3: 45689 | AD3: 45717 | AE3: 45748 | AF3: 45778 | AG3: 45809 | AH3: 45839 | AI3: 45870 | AJ3: 45901 | AK3: 45931 | AL3: 45962 | AM3: 45992
A4: 83520000 | B4: Achat Consommables Industriel | C4: PC | D4: 0 | E4: 0 | F4: 0 | G4: 0 | H4: 0 | I4: 0 | J4: 0 | K4: 0 | L4: 0 | M4: 0 | N4: 0 | O4: 0 | P4: 0 | Q4: 0 | R4: 0 | S4: 0 | T4: 0 | U4: 0 | V4: 0 | W4: 0 | X4: 0 | Y4: 0 | Z4: 0 | AA4: 0 | AB4: 0 | AC4: 0 | AD4: 0 | AE4: -135 | AF4: -141 | AG4: -55 | AH4: -274 | AI4: -41 | AJ4: -15 | AK4: -2 | AL4: -5 | AM4: -17
A5: 76210012 | B5: Rouleau doseur 61x1350mm | C5: PC | D5: 0 | E5: 0 | F5: 0 | G5: 0 | H5: -2 | I5: 0 | J5: 0 | K5: -1 | L5: 0 | M5: 0 | N5: 0 | O5: 0 | P5: -3 | Q5: 0 | R5: 0 | S5: 0 | T5: -1 | U5: -1 | V5: 0 | W5: -1 | X5: 0 | Y5: -1 | Z5: 0 | AA5: -1 | AB5: 0 | AC5: 0 | AD5: -1 | AE5: -1 | AF5: 0 | AG5: -1 | AH5: -1 | AI5: -1 | AJ5: 0 | AK5: 0 | AL5: -1 | AM5: 0
A6: 86100028 | B6: VIS CONE MOBILE M52X300 L639 TH | C6: PC | D6: 0 | E6: 0 | F6: 0 | G6: 0 | H6: 0 | I6: 0 | J6: 0 | K6: 0 | L6: 0 | M6: 0 | N6: -1 | O6: -2 | P6: -2 | Q6: 0 | R6: 0 | S6: 0 | T6: -2 | U6: 0 | V6: 0 | W6: 0 | X6: 0 | Y6: 0 | Z6: -7 | AA6: 0 | AB6: 0 | AC6: -4 | AD6: -2 | AE6: -2 | AF6: 0 | AG6: -4 | AH6: -4 | AI6: 0 | AJ6: -4 | AK6: -2 | AL6: -6 | AM6: -2
A7: 78610122 | B7: VERIN P1D S050 MC 0050-B201211/09/36 | C7: PC | D7: 0 | E7: -10 | F7: -2 | G7: 0 | H7: 0 | I7: 0 | J7: 0 | K7: 0 | L7: -6 | M7: -1 | N7: -1 | O7: 0 | P7: 0 | Q7: 0 | R7: 0 | S7: -3 | T7: -2 | U7: 0 | V7: 0 | W7: -2 | X7: 0 | Y7: -1 | Z7: 0 | AA7: 0 | AB7: 0 | AC7: -2 | AD7: 0 | AE7: 0 | AF7: -4 | AG7: -3 | AH7: 0 | AI7: -1 | AJ7: -1 | AK7: -1 | AL7: -2 | AM7: 0
A8: 78610119 | B8: VERIN P1D SO50-MC0145 B201444-08-48 | C8: PC | D8: 0 | E8: 0 | F8: 0 | G8: 0 | H8: -1 | I8: -1 | J8: 0 | K8: 0 | L8: -1 | M8: 0 | N8: 0 | O8: 0 | P8: 0 | Q8: 0 | R8: -1 | S8: 0 | T8: 0 | U8: 0 | V8: 0 | W8: 0 | X8: 0 | Y8: -1 | Z8: 0 | AA8: 0 | AB8: 0 | AC8: -2 | AD8: 0 | AE8: 0 | AF8: -1 | AG8: -1 | AH8: 0 | AI8: 0 | AJ8: -1 | AK8: 0 | AL8: -1 | AM8: -1
A9: 02020007 | B9: Pet Coke Broyé (HS) | C9: TO | D9: -9609.482 | E9: -9430.197 | F9: -5854.285 | G9: -11701.551 | H9: -12443.063 | I9: -10011.49 | J9: -13566.07 | K9: -12902.759 | L9: -11368.007 | M9: -13620.75 | N9: -12627.372 | O9: -11462.602 | P9: -8847.376 | Q9: -7611.84 | R9: -6992.223 | S9: -7885.485 | T9: -8103.35 | U9: -8139.142 | V9: -7265.079 | W9: -7449.972 | X9: -7819.522 | Y9: -8845.322 | Z9: -8816.541 | AA9: -8651.899 | AB9: -4788.773 | AC9: -3784.039 | AD9: -8137.792 | AE9: -7633.304 | AF9: -8731.546 | AG9: -8377.904 | AH9: -8258.588 | AI9: -6169.313 | AJ9: -7156.232 | AK9: -8368.543 | AL9: -8618.264 | AM9: -8540.682
A10: 59600055 | B10: ELECTROVANNE HT 230V ALTERNATIF AIR CHOC | C10: PC | D10: -3 | E10: 0 | F10: -3 | G10: -1 | H10: 0 | I10: 0 | J10: 0 | K10: 0 | L10: 0 | M10: 0 | N10: -1 | O10: 0 | P10: 0 | Q10: -2 | R10: -1 | S10: 0 | T10: 0 | U10: 0 | V10: 0 | W10: -1 | X10: 0 | Y10: 0 | Z10: 0 | AA10: 0 | AB10: 0 | AC10: -3 | AD10: 0 | AE10: 0 | AF10: 0 | AG10: -2 | AH10: 0 | AI10: 0 | AJ10: -1 | AK10: -2 | AL10: -1 | AM10: -1
A11: 04030001 | B11: Pet Coke Brut (MS) | C11: TO | D11: -4820.615 | E11: -257.519 | F11: 0 | G11: 0 | H11: 0 | I11: 0 | J11: 0 | K11: 0 | L11: 0 | M11: 0 | N11: 0 | O11: 0 | P11: 0 | Q11: 0 | R11: 0 | S11: 0 | T11: 0 | U11: 0 | V11: 0 | W11: 0 | X11: 0 | Y11: 0 | Z11: 0 | AA11: -1451.832 | AB11: -5516.545 | AC11: -4319.657 | AD11: -9602.515 | AE11: -9453.293 | AF11: -10343.219 | AG11: -9943.159 | AH11: -9759.542 | AI11: -7425.773 | AJ11: -8339.611 | AK11: -9298.719 | AL11: -9881.993 | AM11: -7686.328
A12: 71030061 | B12: Bande NHM-10ESBV 2190*600 EP : 03mm | C12: PC | D12: -1 | E12: 0 | F12: 0 | G12: -2 | H12: 0 | I12: 0 | J12: 0 | K12: -1 | L12: -1 | M12: -1 | N12: -1 | O12: -2 | P12: 0 | Q12: -1 | R12: 0 | S12: 0 | T12: 0 | U12: -2 | V12: -1 | W12: 0 | X12: -2 | Y12: -1 | Z12: 0 | AA12: -2 | AB12: -1 | AC12: 0 | AD12: -2 | AE12: 0 | AF12: -1 | AG12: -1 | AH12: 0 | AI12: -2 | AJ12: -1 | AK12: -2 | AL12: 0 | AM12: -2
A13: 65660006 | B13: GALET COMPLET Ø108+AXE (KZB250-800X300X4 | C13: PC | D13: 0 | E13: -42 | F13: 0 | G13: -12 | H13: -12 | I13: 0 | J13: 0 | K13: 0 | L13: -1 | M13: 0 | N13: -6 | O13: -44 | P13: 0 | Q13: 0 | R13: 0 | S13: 0 | T13: 0 | U13: 0 | V13: -2 | W13: -4 | X13: 0 | Y13: -1 | Z13: 0 | AA13: 0 | AB13: -7 | AC13: -10 | AD13: -1 | AE13: 0 | AF13: -5 | AG13: 0 | AH13: -3 | AI13: -56 | AJ13: -1 | AK13: -1 | AL13: 0 | AM13: 0
A14: 45600027 | B14: Acide pour détartrage Treatonet DDB044 | C14: PC | D14: -5 | E14: -20 | F14: -75 | G14: 0 | H14: -25 | I14: 0 | J14: -25 | K14: -25 | L14: -25 | M14: -25 | N14: -25 | O14: 0 | P14: -3 | Q14: 0 | R14: -25 | S14: -50 | T14: 0 | U14: -25 | V14: -50 | W14: -75 | X14: -25 | Y14: 0 | Z14: 0 | AA14: 0 | AB14: -51 | AC14: -75 | AD14: -1 | AE14: 0 | AF14: 0 | AG14: -50 | AH14: -25 | AI14: -50 | AJ14: 0 | AK14: -25 | AL14: 0 | AM14: 0
... A1182: 30090006 | B1182: CHEVILLE PLASTIQUE 6 MM | C1182: PC | D1182: 0 | E1182: 0 | F1182: 0 | G1182: 0 | H1182: 0 | I1182: 0 | J1182: 0 | K1182: 0 | L1182: 0 | M1182: 0 | N1182: 0 | O1182: 0 | P1182: 0 | Q1182: 0 | R1182: -5 | S1182: -25 | T1182: -4 | U1182: 0 | V1182: 0 | W1182: -10 | X1182: 0 | Y1182: 0 | Z1182: 0 | AA1182: 0 | AB1182: 0 | AC1182: 0 | AD1182: 0 | AE1182: -30 | AF1182: 0 | AG1182: 0 | AH1182: 0 | AI1182: 0 | AJ1182: 0 | AK1182: -10 | AL1182: 0 | AM1182: 0

Sheet Classification
A1: Article | B1: Désignation article | C1: Unit. | D1: ABC | E1: HML | F1: PMP
A2: 83520000 | B2: Achat Consommables Industriel | C2: PC | D2: B | E2: =VLOOKUP(A2,[1]HML!$A$2:$D$8104,4,0) -> H | F2: 1212.176
A3: 76210012 | B3: Rouleau doseur 61x1350mm | C3: PC | D3: B | E3: =VLOOKUP(A3,[1]HML!$A$2:$D$8104,4,0) -> H | F3: 903.07
A4: 86100028 | B4: VIS CONE MOBILE M52X300 L639 TH | C4: PC | D4: B | E4: =VLOOKUP(A4,[1]HML!$A$2:$D$8104,4,0) -> H | F4: 808
A5: 78610122 | B5: VERIN P1D S050 MC 0050-B201211/09/36 | C5: PC | D5: B | E5: =VLOOKUP(A5,[1]HML!$A$2:$D$8104,4,0) -> H | F5: 787.245
A6: 78610119 | B6: VERIN P1D SO50-MC0145 B201444-08-48 | C6: PC | D6: B | E6: =VLOOKUP(A6,[1]HML!$A$2:$D$8104,4,0) -> H | F6: 680.5
A7: 02020007 | B7: Pet Coke Broyé (HS) | C7: TO | D7: B | E7: =VLOOKUP(A7,[1]HML!$A$2:$D$8104,4,0) -> H | F7: 520.823
A8: 59600055 | B8: ELECTROVANNE HT 230V ALTERNATIF AIR CHOC | C8: PC | D8: B | E8: =VLOOKUP(A8,[1]HML!$A$2:$D$8104,4,0) -> H | F8: 508.492
A9: 04030001 | B9: Pet Coke Brut (MS) | C9: TO | D9: B | E9: =VLOOKUP(A9,[1]HML!$A$2:$D$8104,4,0) -> H | F9: 497.466
A10: 71030061 | B10: Bande NHM-10ESBV 2190*600 EP : 03mm | C10: PC | D10: B | E10: =VLOOKUP(A10,[1]HML!$A$2:$D$8104,4,0) -> H | F10: 467.418
A11: 65660006 | B11: GALET COMPLET Ø108+AXE (KZB250-800X300X4 | C11: PC | D11: B | E11: =VLOOKUP(A11,[1]HML!$A$2:$D$8104,4,0) -> H | F11: 436.379
A12: 45600027 | B12: Acide pour détartrage Treatonet DDB044 | C12: PC | D12: B | E12: =VLOOKUP(A12,[1]HML!$A$2:$D$8104,4,0) -> H | F12: 425.607
A13: 78610111 | B13: VERIN PID S040 MC 0100 B201215 R:640466Z | C13: PC | D13: B | E13: =VLOOKUP(A13,[1]HML!$A$2:$D$8104,4,0) -> H | F13: 371.378
... A1180: 30090006 | B1180: CHEVILLE PLASTIQUE 6 MM | C1180: PC | D1180: C | E1180: =VLOOKUP(A1180,[1]HML!$A$2:$D$8104,4,0) -> L | F1180: 0.012

Sheet ⚙️ Optimization Parameters
A1: OPTIMIZED STOCK PARAMETERS | U1: Safety Stock, ROP, EOQ, Min, Max calculation
A2: Article | B2: Désignation article | C2: Unit | D2: Source | E2: ABC | F2: HML | G2: Lead Time (Days) | H2: Lead Time (Months) | I2: Unit Cost | J2: Total Consumption | K2: MaxMonthlyDemand | L2: MinNonZeroDemand | M2: ActiveMonths | N2: AvgMonthlyDemand | O2: sum/active months | P2: StdMonthlyDemand | Q2: AvgDailyDemand | R2: StdDailyDemand | S2: Coefficient of Variation (CV) | T2: XYZ classification | U2: Service Level | V2: Z factor | W2: Safety Stock (SS) (M1: Daily) | X2: Safety Stock (SS) (M2: Monthly) | Y2: Reorder Point (ROP) (M1: Daily) | Z2: Reorder Point (ROP) (m2: Monthly) | AA2: Annual demand (D) | AB2: Holding cost per unit | AC2: EOQ (Economic Order Quantity) | AD2: Stock Min | AE2: Stock Max | AF2: Orders per year
A3: 83520000 | B3: Achat Consommables Industriel | C3: PC | D3: =VLOOKUP(A3,'Lead Time'!$A$2:$C$1180,3,0) -> Mixed Source | E3: =VLOOKUP(A3,Classification!$A$2:$D$1180,4,0) -> B | F3: =VLOOKUP(A3,Classification!$A$2:$E$1180,5,0) -> H | G3: =VLOOKUP(A3,'Lead Time'!$A$2:$D$1180,4,0) -> 109.33758 | H3: =G3/30 -> 3.644586 | I3: =VLOOKUP(A3,Classification!$A$2:$F$1180,6,0) -> 1212.176 | J3: =-SUM('cons 2023 - 2025'!D4:AM4) -> 685 | K3: =-_xlfn.MINIFS('cons 2023 - 2025'!D4:AM4,'cons 2023 - 2025'!D4:AM4,"<>0") -> 274 | L3: =-_xlfn.MAXIFS('cons 2023 - 2025'!D4:AM4,'cons 2023 - 2025'!D4:AM4,"<>0") -> 2 | M3: =COUNTIF('cons 2023 - 2025'!D4:AM4,"<>0") -> 9 | N3: =-AVERAGE('cons 2023 - 2025'!D4:AM4) -> 19.027778 | O3: =J3/M3 -> 76.111111 | P3: =_xlfn.STDEV.S('cons 2023 - 2025'!D4:AM4) -> 54.875696 | Q3: =-AVERAGE('cons 2023 - 2025'!D4:AM4)/'⚙ Assumptions'!$B$5 -> 0.86489899 | R3: =_xlfn.STDEV.S('cons 2023 - 2025'!D4:AM4)/SQRT('⚙ Assumptions'!$B$5) -> 11.699538 | S3: =-IF(AVERAGE('cons 2023 - 2025'!D4:AM4)=0,"",_xlfn.STDEV.S('cons 2023 - 2025'!D4:AM4)/AVERAGE('cons 2023 - 2025'!D4:AM4)) -> 2.8839782 | T3: =IF(ISBLANK(S3),"Z", IF(S3<=0.25,"X", IF(S3<=0.5,"Y","Z"))) -> Z | U3: =IF(E3="B",0.95,IF(E3="C",0.9,0.98)) -> 0.95 | V3: =IF(E3="B",1.65,1.28) -> 1.65 | W3: =V3*R3*SQRT(G3) -> 201.85401 | X3: =V3*P3*SQRT(H3) -> 172.85745 | Y3: =Q3*G3+W3 -> 296.41997 | Z3: =N3*H3+X3 -> 242.20582 | AA3: =-AVERAGE('cons 2023 - 2025'!D4:AM4)*12 -> 228.33333 | AB3: =I3*0.2 -> 242.4352 | AC3: =SQRT((2*AA3*'⚙ Assumptions'!$B$3)/AB3) -> 16.809216 | AD3: =Z3 -> 242.20582 | AE3: =Z3+AC3 -> 259.01503 | AF3: =AA3/AC3 -> 13.583818
A4: 76210012 | B4: Rouleau doseur 61x1350mm | C4: PC | D4: =VLOOKUP(A4,'Lead Time'!$A$2:$C$1180,3,0) -> Import | E4: =VLOOKUP(A4,Classification!$A$2:$D$1180,4,0) -> B | F4: =VLOOKUP(A4,Classification!$A$2:$E$1180,5,0) -> H | G4: =VLOOKUP(A4,'Lead Time'!$A$2:$D$1180,4,0) -> 283.2 | H4: =G4/30 -> 9.44 | I4: =VLOOKUP(A4,Classification!$A$2:$F$1180,6,0) -> 903.07 | J4: =-SUM('cons 2023 - 2025'!D5:AM5) -> 17 | K4: =-_xlfn.MINIFS('cons 2023 - 2025'!D5:AM5,'cons 2023 - 2025'!D5:AM5,"<>0") -> 3 | L4: =-_xlfn.MAXIFS('cons 2023 - 2025'!D5:AM5,'cons 2023 - 2025'!D5:AM5,"<>0") -> 1 | M4: =COUNTIF('cons 2023 - 2025'!D5:AM5,"<>0") -> 14 | N4: =-AVERAGE('cons 2023 - 2025'!D5:AM5) -> 0.47222222 | O4: =J4/M4 -> 1.2142857 | P4: =_xlfn.STDEV.S('cons 2023 - 2025'!D5:AM5) -> 0.69636243 | Q4: =-AVERAGE('cons 2023 - 2025'!D5:AM5)/'⚙ Assumptions'!$B$5 -> 0.021464646 | R4: =_xlfn.STDEV.S('cons 2023 - 2025'!D5:AM5)/SQRT('⚙ Assumptions'!$B$5) -> 0.14846497 | S4: =-IF(AVERAGE('cons 2023 - 2025'!D5:AM5)=0,"",_xlfn.STDEV.S('cons 2023 - 2025'!D5:AM5)/AVERAGE('cons 2023 - 2025'!D5:AM5)) -> 1.4746499 | T4: =IF(ISBLANK(S4),"Z", IF(S4<=0.25,"X", IF(S4<=0.5,"Y","Z"))) -> Z | U4: =IF(E4="B",0.95,IF(E4="C",0.9,0.98)) -> 0.95 | V4: =IF(E4="B",1.65,1.28) -> 1.65 | W4: =V4*R4*SQRT(G4) -> 4.1224421 | X4: =V4*P4*SQRT(H4) -> 3.5302485 | Y4: =Q4*G4+W4 -> 10.20123 | Z4: =N4*H4+X4 -> 7.9880263 | AA4: =-AVERAGE('cons 2023 - 2025'!D5:AM5)*12 -> 5.6666667 | AB4: =I4*0.2 -> 180.614 | AC4: =SQRT((2*AA4*'⚙ Assumptions'!$B$3)/AB4) -> 3.0679534 | AD4: =Z4 -> 7.9880263 | AE4: =Z4+AC4 -> 11.05598 | AF4: =AA4/AC4 -> 1.8470511
A5: 86100028 | B5: VIS CONE MOBILE M52X300 L639 TH | C5: PC | D5: =VLOOKUP(A5,'Lead Time'!$A$2:$C$1180,3,0) -> Local | E5: =VLOOKUP(A5,Classification!$A$2:$D$1180,4,0) -> B | F5: =VLOOKUP(A5,Classification!$A$2:$E$1180,5,0) -> H | G5: =VLOOKUP(A5,'Lead Time'!$A$2:$D$1180,4,0) -> 15.8 | H5: =G5/30 -> 0.52666667 | I5: =VLOOKUP(A5,Classification!$A$2:$F$1180,6,0) -> 808 | J5: =-SUM('cons 2023 - 2025'!D6:AM6) -> 44 | K5: =-_xlfn.MINIFS('cons 2023 - 2025'!D6:AM6,'cons 2023 - 2025'!D6:AM6,"<>0") -> 7 | L5: =-_xlfn.MAXIFS('cons 2023 - 2025'!D6:AM6,'cons 2023 - 2025'!D6:AM6,"<>0") -> 1 | M5: =COUNTIF('cons 2023 - 2025'!D6:AM6,"<>0") -> 14 | N5: =-AVERAGE('cons 2023 - 2025'!D6:AM6) -> 1.2222222 | O5: =J5/M5 -> 3.1428571 | P5: =_xlfn.STDEV.S('cons 2023 - 2025'!D6:AM6) -> 1.8839337 | Q5: =-AVERAGE('cons 2023 - 2025'!D6:AM6)/'⚙ Assumptions'!$B$5 -> 0.055555556 | R5: =_xlfn.STDEV.S('cons 2023 - 2025'!D6:AM6)/SQRT('⚙ Assumptions'!$B$5) -> 0.40165602 | S5: =-IF(AVERAGE('cons 2023 - 2025'!D6:AM6)=0,"",_xlfn.STDEV.S('cons 2023 - 2025'!D6:AM6)/AVERAGE('cons 2023 - 2025'!D6:AM6)) -> 1.5414003 | T5: =IF(ISBLANK(S5),"Z", IF(S5<=0.25,"X", IF(S5<=0.5,"Y","Z"))) -> Z | U5: =IF(E5="B",0.95,IF(E5="C",0.9,0.98)) -> 0.95 | V5: =IF(E5="B",1.65,1.28) -> 1.65 | W5: =V5*R5*SQRT(G5) -> 2.6343093 | X5: =V5*P5*SQRT(H5) -> 2.2558877 | Y5: =Q5*G5+W5 -> 3.5120871 | Z5: =N5*H5+X5 -> 2.8995914 | AA5: =-AVERAGE('cons 2023 - 2025'!D6:AM6)*12 -> 14.666667 | AB5: =I5*0.2 -> 161.6 | AC5: =SQRT((2*AA5*'⚙ Assumptions'!$B$3)/AB5) -> 5.218019 | AD5: =Z5 -> 2.8995914 | AE5: =Z5+AC5 -> 8.1176105 | AF5: =AA5/AC5 -> 2.8107729
A6: 78610122 | B6: VERIN P1D S050 MC 0050-B201211/09/36 | C6: PC | D6: =VLOOKUP(A6,'Lead Time'!$A$2:$C$1180,3,0) -> Mixed Source | E6: =VLOOKUP(A6,Classification!$A$2:$D$1180,4,0) -> B | F6: =VLOOKUP(A6,Classification!$A$2:$E$1180,5,0) -> H | G6: =VLOOKUP(A6,'Lead Time'!$A$2:$D$1180,4,0) -> 79.160714 | H6: =G6/30 -> 2.6386905 | I6: =VLOOKUP(A6,Classification!$A$2:$F$1180,6,0) -> 787.245 | J6: =-SUM('cons 2023 - 2025'!D7:AM7) -> 42 | K6: =-_xlfn.MINIFS('cons 2023 - 2025'!D7:AM7,'cons 2023 - 2025'!D7:AM7,"<>0") -> 10 | L6: =-_xlfn.MAXIFS('cons 2023 - 2025'!D7:AM7,'cons 2023 - 2025'!D7:AM7,"<>0") -> 1 | M6: =COUNTIF('cons 2023 - 2025'!D7:AM7,"<>0") -> 16 | N6: =-AVERAGE('cons 2023 - 2025'!D7:AM7) -> 1.1666667 | O6: =J6/M6 -> 2.625 | P6: =_xlfn.STDEV.S('cons 2023 - 2025'!D7:AM7) -> 2.0493902 | Q6: =-AVERAGE('cons 2023 - 2025'!D7:AM7)/'⚙ Assumptions'!$B$5 -> 0.053030303 | R6: =_xlfn.STDEV.S('cons 2023 - 2025'!D7:AM7)/SQRT('⚙ Assumptions'!$B$5) -> 0.43693145 | S6: =-IF(AVERAGE('cons 2023 - 2025'!D7:AM7)=0,"",_xlfn.STDEV.S('cons 2023 - 2025'!D7:AM7)/AVERAGE('cons 2023 - 2025'!D7:AM7)) -> 1.7566201 | T6: =IF(ISBLANK(S6),"Z", IF(S6<=0.25,"X", IF(S6<=0.5,"Y","Z"))) -> Z | U6: =IF(E6="B",0.95,IF(E6="C",0.9,0.98)) -> 0.95 | V6: =IF(E6="B",1.65,1.28) -> 1.65 | W6: =V6*R6*SQRT(G6) -> 6.4143418 | X6: =V6*P6*SQRT(H6) -> 5.4929142 | Y6: =Q6*G6+W6 -> 10.612259 | Z6: =N6*H6+X6 -> 8.5713864 | AA6: =-AVERAGE('cons 2023 - 2025'!D7:AM7)*12 -> 14 | AB6: =I6*0.2 -> 157.449 | AC6: =SQRT((2*AA6*'⚙ Assumptions'!$B$3)/AB6) -> 5.1648141 | AD6: =Z6 -> 8.5713864 | AE6: =Z6+AC6 -> 13.7362 | AF6: =AA6/AC6 -> 2.7106494
A7: 78610119 | B7: VERIN P1D SO50-MC0145 B201444-08-48 | C7: PC | D7: =VLOOKUP(A7,'Lead Time'!$A$2:$C$1180,3,0) -> Mixed Source | E7: =VLOOKUP(A7,Classification!$A$2:$D$1180,4,0) -> B | F7: =VLOOKUP(A7,Classification!$A$2:$E$1180,5,0) -> H | G7: =VLOOKUP(A7,'Lead Time'!$A$2:$D$1180,4,0) -> 93.428571 | H7: =G7/30 -> 3.1142857 | I7: =VLOOKUP(A7,Classification!$A$2:$F$1180,6,0) -> 680.5 | J7: =-SUM('cons 2023 - 2025'!D8:AM8) -> 12 | K7: =-_xlfn.MINIFS('cons 2023 - 2025'!D8:AM8,'cons 2023 - 2025'!D8:AM8,"<>0") -> 2 | L7: =-_xlfn.MAXIFS('cons 2023 - 2025'!D8:AM8,'cons 2023 - 2025'!D8:AM8,"<>0") -> 1 | M7: =COUNTIF('cons 2023 - 2025'!D8:AM8,"<>0") -> 11 | N7: =-AVERAGE('cons 2023 - 2025'!D8:AM8) -> 0.33333333 | O7: =J7/M7 -> 1.0909091 | P7: =_xlfn.STDEV.S('cons 2023 - 2025'!D8:AM8) -> 0.53452248 | Q7: =-AVERAGE('cons 2023 - 2025'!D8:AM8)/'⚙ Assumptions'!$B$5 -> 0.015151515 | R7: =_xlfn.STDEV.S('cons 2023 - 2025'!D8:AM8)/SQRT('⚙ Assumptions'!$B$5) -> 0.11396058 | S7: =-IF(AVERAGE('cons 2023 - 2025'!D8:AM8)=0,"",_xlfn.STDEV.S('cons 2023 - 2025'!D8:AM8)/AVERAGE('cons 2023 - 2025'!D8:AM8)) -> 1.6035675 | T7: =IF(ISBLANK(S7),"Z", IF(S7<=0.25,"X", IF(S7<=0.5,"Y","Z"))) -> Z | U7: =IF(E7="B",0.95,IF(E7="C",0.9,0.98)) -> 0.95 | V7: =IF(E7="B",1.65,1.28) -> 1.65 | W7: =V7*R7*SQRT(G7) -> 1.8175168 | X7: =V7*P7*SQRT(H7) -> 1.5564284 | Y7: =Q7*G7+W7 -> 3.2331012 | Z7: =N7*H7+X7 -> 2.5945236 | AA7: =-AVERAGE('cons 2023 - 2025'!D8:AM8)*12 -> 4 | AB7: =I7*0.2 -> 136.1 | AC7: =SQRT((2*AA7*'⚙ Assumptions'!$B$3)/AB7) -> 2.9693512 | AD7: =Z7 -> 2.5945236 | AE7: =Z7+AC7 -> 5.5638748 | AF7: =AA7/AC7 -> 1.3470956
A8: 02020007 | B8: Pet Coke Broyé (HS) | C8: TO | E8: =VLOOKUP(A8,Classification!$A$2:$D$1180,4,0) -> B | F8: =VLOOKUP(A8,Classification!$A$2:$E$1180,5,0) -> H | G8: =VLOOKUP(A8,'Lead Time'!$A$2:$D$1180,4,0) -> 44 | H8: =G8/30 -> 1.4666667 | I8: =VLOOKUP(A8,Classification!$A$2:$F$1180,6,0) -> 520.823 | J8: =-SUM('cons 2023 - 2025'!D9:AM9) -> 319590.36 | K8: =-_xlfn.MINIFS('cons 2023 - 2025'!D9:AM9,'cons 2023 - 2025'!D9:AM9,"<>0") -> 13620.75 | L8: =-_xlfn.MAXIFS('cons 2023 - 2025'!D9:AM9,'cons 2023 - 2025'!D9:AM9,"<>0") -> 3784.039 | M8: =COUNTIF('cons 2023 - 2025'!D9:AM9,"<>0") -> 36 | N8: =-AVERAGE('cons 2023 - 2025'!D9:AM9) -> 8877.51 | O8: =J8/M8 -> 8877.51 | P8: =_xlfn.STDEV.S('cons 2023 - 2025'!D9:AM9) -> 2322.7541 | Q8: =-AVERAGE('cons 2023 - 2025'!D9:AM9)/'⚙ Assumptions'!$B$5 -> 403.52318 | R8: =_xlfn.STDEV.S('cons 2023 - 2025'!D9:AM9)/SQRT('⚙ Assumptions'!$B$5) -> 495.21283 | S8: =-IF(AVERAGE('cons 2023 - 2025'!D9:AM9)=0,"",_xlfn.STDEV.S('cons 2023 - 2025'!D9:AM9)/AVERAGE('cons 2023 - 2025'!D9:AM9)) -> 0.26164477 | T8: =IF(ISBLANK(S8),"Z", IF(S8<=0.25,"X", IF(S8<=0.5,"Y","Z"))) -> Y | U8: =IF(E8="B",0.95,IF(E8="C",0.9,0.98)) -> 0.95 | V8: =IF(E8="B",1.65,1.28) -> 1.65 | W8: =V8*R8*SQRT(G8) -> 5420.036 | X8: =V8*P8*SQRT(H8) -> 4641.4415 | Y8: =Q8*G8+W8 -> 23175.056 | Z8: =N8*H8+X8 -> 17661.789 | AA8: =-AVERAGE('cons 2023 - 2025'!D9:AM9)*12 -> 106530.12 | AB8: =I8*0.2 -> 104.1646 | AC8: =SQRT((2*AA8*'⚙ Assumptions'!$B$3)/AB8) -> 553.90688 | AD8: =Z8 -> 17661.789 | AE8: =Z8+AC8 -> 18215.696 | AF8: =AA8/AC8 -> 192.32496
A9: 59600055 | B9: ELECTROVANNE HT 230V ALTERNATIF AIR CHOC | C9: PC | D9: =VLOOKUP(A9,'Lead Time'!$A$2:$C$1180,3,0) -> Import | E9: =VLOOKUP(A9,Classification!$A$2:$D$1180,4,0) -> B | F9: =VLOOKUP(A9,Classification!$A$2:$E$1180,5,0) -> H | G9: =VLOOKUP(A9,'Lead Time'!$A$2:$D$1180,4,0) -> 74.5 | H9: =G9/30 -> 2.4833333 | I9: =VLOOKUP(A9,Classification!$A$2:$F$1180,6,0) -> 508.492 | J9: =-SUM('cons 2023 - 2025'!D10:AM10) -> 22 | K9: =-_xlfn.MINIFS('cons 2023 - 2025'!D10:AM10,'cons 2023 - 2025'!D10:AM10,"<>0") -> 3 | L9: =-_xlfn.MAXIFS('cons 2023 - 2025'!D10:AM10,'cons 2023 - 2025'!D10:AM10,"<>0") -> 1 | M9: =COUNTIF('cons 2023 - 2025'!D10:AM10,"<>0") -> 13 | N9: =-AVERAGE('cons 2023 - 2025'!D10:AM10) -> 0.61111111 | O9: =J9/M9 -> 1.6923077 | P9: =_xlfn.STDEV.S('cons 2023 - 2025'!D10:AM10) -> 0.96444737 | Q9: =-AVERAGE('cons 2023 - 2025'!D10:AM10)/'⚙ Assumptions'!$B$5 -> 0.027777778 | R9: =_xlfn.STDEV.S('cons 2023 - 2025'!D10:AM10)/SQRT('⚙ Assumptions'!$B$5) -> 0.20562087 | S9: =-IF(AVERAGE('cons 2023 - 2025'!D10:AM10)=0,"",_xlfn.STDEV.S('cons 2023 - 2025'!D10:AM10)/AVERAGE('cons 2023 - 2025'!D10:AM10)) -> 1.5781866 | T9: =IF(ISBLANK(S9),"Z", IF(S9<=0.25,"X", IF(S9<=0.5,"Y","Z"))) -> Z | U9: =IF(E9="B",0.95,IF(E9="C",0.9,0.98)) -> 0.95 | V9: =IF(E9="B",1.65,1.28) -> 1.65 | W9: =V9*R9*SQRT(G9) -> 2.9283924 | X9: =V9*P9*SQRT(H9) -> 2.5077254 | Y9: =Q9*G9+W9 -> 4.9978369 | Z9: =N9*H9+X9 -> 4.025318 | AA9: =-AVERAGE('cons 2023 - 2025'!D10:AM10)*12 -> 7.3333333 | AB9: =I9*0.2 -> 101.6984 | AC9: =SQRT((2*AA9*'⚙ Assumptions'!$B$3)/AB9) -> 4.651085 | AD9: =Z9 -> 4.025318 | AE9: =Z9+AC9 -> 8.6764031 | AF9: =AA9/AC9 -> 1.576693
A10: 04030001 | B10: Pet Coke Brut (MS) | C10: TO | D10: =VLOOKUP(A10,'Lead Time'!$A$2:$C$1180,3,0) -> Import | E10: =VLOOKUP(A10,Classification!$A$2:$D$1180,4,0) -> B | F10: =VLOOKUP(A10,Classification!$A$2:$E$1180,5,0) -> H | G10: =VLOOKUP(A10,'Lead Time'!$A$2:$D$1180,4,0) -> 17.960784 | H10: =G10/30 -> 0.59869281 | I10: =VLOOKUP(A10,Classification!$A$2:$F$1180,6,0) -> 497.466 | J10: =-SUM('cons 2023 - 2025'!D11:AM11) -> 108100.32 | K10: =-_xlfn.MINIFS('cons 2023 - 2025'!D11:AM11,'cons 2023 - 2025'!D11:AM11,"<>0") -> 10343.219 | L10: =-_xlfn.MAXIFS('cons 2023 - 2025'!D11:AM11,'cons 2023 - 2025'!D11:AM11,"<>0") -> 257.519 | M10: =COUNTIF('cons 2023 - 2025'!D11:AM11,"<>0") -> 15 | N10: =-AVERAGE('cons 2023 - 2025'!D11:AM11) -> 3002.7867 | O10: =J10/M10 -> 7206.688 | P10: =_xlfn.STDEV.S('cons 2023 - 2025'!D11:AM11) -> 4141.9908 | Q10: =-AVERAGE('cons 2023 - 2025'!D11:AM11)/'⚙ Assumptions'!$B$5 -> 136.4903 | R10: =_xlfn.STDEV.S('cons 2023 - 2025'!D11:AM11)/SQRT('⚙ Assumptions'!$B$5) -> 883.07541 | S10: =-IF(AVERAGE('cons 2023 - 2025'!D11:AM11)=0,"",_xlfn.STDEV.S('cons 2023 - 2025'!D11:AM11)/AVERAGE('cons 2023 - 2025'!D11:AM11)) -> 1.3793823 | T10: =IF(ISBLANK(S10),"Z", IF(S10<=0.25,"X", IF(S10<=0.5,"Y","Z"))) -> Z | U10: =IF(E10="B",0.95,IF(E10="C",0.9,0.98)) -> 0.95 | V10: =IF(E10="B",1.65,1.28) -> 1.65 | W10: =V10*R10*SQRT(G10) -> 6175.1055 | X10: =V10*P10*SQRT(H10) -> 5288.0444 | Y10: =Q10*G10+W10 -> 8626.5784 | Z10: =N10*H10+X10 -> 7085.7912 | AA10: =-AVERAGE('cons 2023 - 2025'!D11:AM11)*12 -> 36033.44 | AB10: =I10*0.2 -> 99.4932 | AC10: =SQRT((2*AA10*'⚙ Assumptions'!$B$3)/AB10) -> 329.62246 | AD10: =Z10 -> 7085.7912 | AE10: =Z10+AC10 -> 7415.4137 | AF10: =AA10/AC10 -> 109.31731
A11: 71030061 | B11: Bande NHM-10ESBV 2190*600 EP : 03mm | C11: PC | D11: =VLOOKUP(A11,'Lead Time'!$A$2:$C$1180,3,0) -> Local | E11: =VLOOKUP(A11,Classification!$A$2:$D$1180,4,0) -> B | F11: =VLOOKUP(A11,Classification!$A$2:$E$1180,5,0) -> H | G11: =VLOOKUP(A11,'Lead Time'!$A$2:$D$1180,4,0) -> 19.466667 | H11: =G11/30 -> 0.64888889 | I11: =VLOOKUP(A11,Classification!$A$2:$F$1180,6,0) -> 467.418 | J11: =-SUM('cons 2023 - 2025'!D12:AM12) -> 30 | K11: =-_xlfn.MINIFS('cons 2023 - 2025'!D12:AM12,'cons 2023 - 2025'!D12:AM12,"<>0") -> 2 | L11: =-_xlfn.MAXIFS('cons 2023 - 2025'!D12:AM12,'cons 2023 - 2025'!D12:AM12,"<>0") -> 1 | M11: =COUNTIF('cons 2023 - 2025'!D12:AM12,"<>0") -> 21 | N11: =-AVERAGE('cons 2023 - 2025'!D12:AM12) -> 0.83333333 | O11: =J11/M11 -> 1.4285714 | P11: =_xlfn.STDEV.S('cons 2023 - 2025'!D12:AM12) -> 0.81064348 | Q11: =-AVERAGE('cons 2023 - 2025'!D12:AM12)/'⚙ Assumptions'!$B$5 -> 0.037878788 | R11: =_xlfn.STDEV.S('cons 2023 - 2025'!D12:AM12)/SQRT('⚙ Assumptions'!$B$5) -> 0.17282977 | S11: =-IF(AVERAGE('cons 2023 - 2025'!D12:AM12)=0,"",_xlfn.STDEV.S('cons 2023 - 2025'!D12:AM12)/AVERAGE('cons 2023 - 2025'!D12:AM12)) -> 0.97277218 | T11: =IF(ISBLANK(S11),"Z", IF(S11<=0.25,"X", IF(S11<=0.5,"Y","Z"))) -> Z | U11: =IF(E11="B",0.95,IF(E11="C",0.9,0.98)) -> 0.95 | V11: =IF(E11="B",1.65,1.28) -> 1.65 | W11: =V11*R11*SQRT(G11) -> 1.258196 | X11: =V11*P11*SQRT(H11) -> 1.0774547 | Y11: =Q11*G11+W11 -> 1.9955697 | Z11: =N11*H11+X11 -> 1.6181954 | AA11: =-AVERAGE('cons 2023 - 2025'!D12:AM12)*12 -> 10 | AB11: =I11*0.2 -> 93.4836 | AC11: =SQRT((2*AA11*'⚙ Assumptions'!$B$3)/AB11) -> 5.6649087 | AD11: =Z11 -> 1.6181954 | AE11: =Z11+AC11 -> 7.2831041 | AF11: =AA11/AC11 -> 1.7652535
A12: 65660006 | B12: GALET COMPLET Ø108+AXE (KZB250-800X300X4 | C12: PC | D12: =VLOOKUP(A12,'Lead Time'!$A$2:$C$1180,3,0) -> Mixed Source | E12: =VLOOKUP(A12,Classification!$A$2:$D$1180,4,0) -> B | F12: =VLOOKUP(A12,Classification!$A$2:$E$1180,5,0) -> H | G12: =VLOOKUP(A12,'Lead Time'!$A$2:$D$1180,4,0) -> 53.8 | H12: =G12/30 -> 1.7933333 | I12: =VLOOKUP(A12,Classification!$A$2:$F$1180,6,0) -> 436.379 | J12: =-SUM('cons 2023 - 2025'!D13:AM13) -> 208 | K12: =-_xlfn.MINIFS('cons 2023 - 2025'!D13:AM13,'cons 2023 - 2025'!D13:AM13,"<>0") -> 56 | L12: =-_xlfn.MAXIFS('cons 2023 - 2025'!D13:AM13,'cons 2023 - 2025'!D13:AM13,"<>0") -> 1 | M12: =COUNTIF('cons 2023 - 2025'!D13:AM13,"<>0") -> 17 | N12: =-AVERAGE('cons 2023 - 2025'!D13:AM13) -> 5.7777778 | O12: =J12/M12 -> 12.235294 | P12: =_xlfn.STDEV.S('cons 2023 - 2025'!D13:AM13) -> 13.273198 | Q12: =-AVERAGE('cons 2023 - 2025'!D13:AM13)/'⚙ Assumptions'!$B$5 -> 0.26262626 | R12: =_xlfn.STDEV.S('cons 2023 - 2025'!D13:AM13)/SQRT('⚙ Assumptions'!$B$5) -> 2.8298553 | S12: =-IF(AVERAGE('cons 2023 - 2025'!D13:AM13)=0,"",_xlfn.STDEV.S('cons 2023 - 2025'!D13:AM13)/AVERAGE('cons 2023 - 2025'!D13:AM13)) -> 2.2972842 | T12: =IF(ISBLANK(S12),"Z", IF(S12<=0.25,"X", IF(S12<=0.5,"Y","Z"))) -> Z | U12: =IF(E12="B",0.95,IF(E12="C",0.9,0.98)) -> 0.95 | V12: =IF(E12="B",1.65,1.28) -> 1.65 | W12: =V12*R12*SQRT(G12) -> 34.248323 | X12: =V12*P12*SQRT(H12) -> 29.328511 | Y12: =Q12*G12+W12 -> 48.377616 | Z12: =N12*H12+X12 -> 39.689993 | AA12: =-AVERAGE('cons 2023 - 2025'!D13:AM13)*12 -> 69.333333 | AB12: =I12*0.2 -> 87.2758 | AC12: =SQRT((2*AA12*'⚙ Assumptions'!$B$3)/AB12) -> 15.437776 | AD12: =Z12 -> 39.689993 | AE12: =Z12+AC12 -> 55.127769 | AF12: =AA12/AC12 -> 4.4911476
A13: 45600027 | B13: Acide pour détartrage Treatonet DDB044 | C13: PC | D13: =VLOOKUP(A13,'Lead Time'!$A$2:$C$1180,3,0) -> Local | E13: =VLOOKUP(A13,Classification!$A$2:$D$1180,4,0) -> B | F13: =VLOOKUP(A13,Classification!$A$2:$E$1180,5,0) -> H | G13: =VLOOKUP(A13,'Lead Time'!$A$2:$D$1180,4,0) -> 13.583333 | H13: =G13/30 -> 0.45277778 | I13: =VLOOKUP(A13,Classification!$A$2:$F$1180,6,0) -> 425.607 | J13: =-SUM('cons 2023 - 2025'!D14:AM14) -> 780 | K13: =-_xlfn.MINIFS('cons 2023 - 2025'!D14:AM14,'cons 2023 - 2025'!D14:AM14,"<>0") -> 75 | L13: =-_xlfn.MAXIFS('cons 2023 - 2025'!D14:AM14,'cons 2023 - 2025'!D14:AM14,"<>0") -> 1 | M13: =COUNTIF('cons 2023 - 2025'!D14:AM14,"<>0") -> 23 | N13: =-AVERAGE('cons 2023 - 2025'!D14:AM14) -> 21.666667 | O13: =J13/M13 -> 33.913043 | P13: =_xlfn.STDEV.S('cons 2023 - 2025'!D14:AM14) -> 23.836347 | Q13: =-AVERAGE('cons 2023 - 2025'!D14:AM14)/'⚙ Assumptions'!$B$5 -> 0.98484848 | R13: =_xlfn.STDEV.S('cons 2023 - 2025'!D14:AM14)/SQRT('⚙ Assumptions'!$B$5) -> 5.0819262 | S13: =-IF(AVERAGE('cons 2023 - 2025'!D14:AM14)=0,"",_xlfn.STDEV.S('cons 2023 - 2025'!D14:AM14)/AVERAGE('cons 2023 - 2025'!D14:AM14)) -> 1.1001391 | T13: =IF(ISBLANK(S13),"Z", IF(S13<=0.25,"X", IF(S13<=0.5,"Y","Z"))) -> Z | U13: =IF(E13="B",0.95,IF(E13="C",0.9,0.98)) -> 0.95 | V13: =IF(E13="B",1.65,1.28) -> 1.65 | W13: =V13*R13*SQRT(G13) -> 30.904056 | X13: =V13*P13*SQRT(H13) -> 26.464652 | Y13: =Q13*G13+W13 -> 44.281581 | Z13: =N13*H13+X13 -> 36.274837 | AA13: =-AVERAGE('cons 2023 - 2025'!D14:AM14)*12 -> 260 | AB13: =I13*0.2 -> 85.1214 | AC13: =SQRT((2*AA13*'⚙ Assumptions'!$B$3)/AB13) -> 30.27108 | AD13: =Z13 -> 36.274837 | AE13: =Z13+AC13 -> 66.545918 | AF13: =AA13/AC13 -> 8.5890558
A14: 78610111 | B14: VERIN PID S040 MC 0100 B201215 R:640466Z | C14: PC | D14: =VLOOKUP(A14,'Lead Time'!$A$2:$C$1180,3,0) -> Mixed Source | E14: =VLOOKUP(A14,Classification!$A$2:$D$1180,4,0) -> B | F14: =VLOOKUP(A14,Classification!$A$2:$E$1180,5,0) -> H | G14: =VLOOKUP(A14,'Lead Time'!$A$2:$D$1180,4,0) -> 42.002717 | H14: =G14/30 -> 1.4000906 | I14: =VLOOKUP(A14,Classification!$A$2:$F$1180,6,0) -> 371.378 | J14: =-SUM('cons 2023 - 2025'!D15:AM15) -> 79 | K14: =-_xlfn.MINIFS('cons 2023 - 2025'!D15:AM15,'cons 2023 - 2025'!D15:AM15,"<>0") -> 8 | L14: =-_xlfn.MAXIFS('cons 2023 - 2025'!D15:AM15,'cons 2023 - 2025'!D15:AM15,"<>0") -> 1 | M14: =COUNTIF('cons 2023 - 2025'!D15:AM15,"<>0") -> 27 | N14: =-AVERAGE('cons 2023 - 2025'!D15:AM15) -> 2.1944444 | O14: =J14/M14 -> 2.9259259 | P14: =_xlfn.STDEV.S('cons 2023 - 2025'!D15:AM15) -> 2.1087497 | Q14: =-AVERAGE('cons 2023 - 2025'!D15:AM15)/'⚙ Assumptions'!$B$5 -> 0.099747475 | R14: =_xlfn.STDEV.S('cons 2023 - 2025'!D15:AM15)/SQRT('⚙ Assumptions'!$B$5) -> 0.44958695 | S14: =-IF(AVERAGE('cons 2023 - 2025'!D15:AM15)=0,"",_xlfn.STDEV.S('cons 2023 - 2025'!D15:AM15)/AVERAGE('cons 2023 - 2025'!D15:AM15)) -> 0.96094924 | T14: =IF(ISBLANK(S14),"Z", IF(S14<=0.25,"X", IF(S14<=0.5,"Y","Z"))) -> Z | U14: =IF(E14="B",0.95,IF(E14="C",0.9,0.98)) -> 0.95 | V14: =IF(E14="B",1.65,1.28) -> 1.65 | W14: =V14*R14*SQRT(G14) -> 4.8076887 | X14: =V14*P14*SQRT(H14) -> 4.1170586 | Y14: =Q14*G14+W14 -> 8.9973537 | Z14: =N14*H14+X14 -> 7.1894796 | AA14: =-AVERAGE('cons 2023 - 2025'!D15:AM15)*12 -> 26.333333 | AB14: =I14*0.2 -> 74.2756 | AC14: =SQRT((2*AA14*'⚙ Assumptions'!$B$3)/AB14) -> 10.313129 | AD14: =Z14 -> 7.1894796 | AE14: =Z14+AC14 -> 17.502609 | AF14: =AA14/AC14 -> 2.5533795
A15: 78610124 | B15: VERIN 241Z25B040XP M.WORK ref:641802D | C15: PC | D15: =VLOOKUP(A15,'Lead Time'!$A$2:$C$1180,3,0) -> Local | E15: =VLOOKUP(A15,Classification!$A$2:$D$1180,4,0) -> B | F15: =VLOOKUP(A15,Classification!$A$2:$E$1180,5,0) -> H | G15: =VLOOKUP(A15,'Lead Time'!$A$2:$D$1180,4,0) -> 18.666667 | H15: =G15/30 -> 0.62222222 | I15: =VLOOKUP(A15,Classification!$A$2:$F$1180,6,0) -> 370.069 | J15: =-SUM('cons 2023 - 2025'!D16:AM16) -> 49 | K15: =-_xlfn.MINIFS('cons 2023 - 2025'!D16:AM16,'cons 2023 - 2025'!D16:AM16,"<>0") -> 4 | L15: =-_xlfn.MAXIFS('cons 2023 - 2025'!D16:AM16,'cons 2023 - 2025'!D16:AM16,"<>0") -> 1 | M15: =COUNTIF('cons 2023 - 2025'!D16:AM16,"<>0") -> 23 | N15: =-AVERAGE('cons 2023 - 2025'!D16:AM16) -> 1.3611111 | O15: =J15/M15 -> 2.1304348 | P15: =_xlfn.STDEV.S('cons 2023 - 2025'!D16:AM16) -> 1.3342259 | Q15: =-AVERAGE('cons 2023 - 2025'!D16:AM16)/'⚙ Assumptions'!$B$5 -> 0.061868687 | R15: =_xlfn.STDEV.S('cons 2023 - 2025'!D16:AM16)/SQRT('⚙ Assumptions'!$B$5) -> 0.28445792 | S15: =-IF(AVERAGE('cons 2023 - 2025'!D16:AM16)=0,"",_xlfn.STDEV.S('cons 2023 - 2025'!D16:AM16)/AVERAGE('cons 2023 - 2025'!D16:AM16)) -> 0.98024759 | T15: =IF(ISBLANK(S15),"Z", IF(S15<=0.25,"X", IF(S15<=0.5,"Y","Z"))) -> Z | U15: =IF(E15="B",0.95,IF(E15="C",0.9,0.98)) -> 0.95 | V15: =IF(E15="B",1.65,1.28) -> 1.65 | W15: =V15*R15*SQRT(G15) -> 2.0278478 | X15: =V15*P15*SQRT(H15) -> 1.7365451 | Y15: =Q15*G15+W15 -> 3.1827299 | Z15: =N15*H15+X15 -> 2.5834587 | AA15: =-AVERAGE('cons 2023 - 2025'!D16:AM16)*12 -> 16.333333 | AB15: =I15*0.2 -> 74.0138 | AC15: =SQRT((2*AA15*'⚙ Assumptions'!$B$3)/AB15) -> 8.1365761 | AD15: =Z15 -> 2.5834587 | AE15: =Z15+AC15 -> 10.720035 | AF15: =AA15/AC15 -> 2.0073964
A16: 40010001 | B16: CHARGE ACYTELENE ALTOP | C16: BT. | D16: =VLOOKUP(A16,'Lead Time'!$A$2:$C$1180,3,0) -> Local | E16: =VLOOKUP(A16,Classification!$A$2:$D$1180,4,0) -> B | F16: =VLOOKUP(A16,Classification!$A$2:$E$1180,5,0) -> H | G16: =VLOOKUP(A16,'Lead Time'!$A$2:$D$1180,4,0) -> 14.62069 | H16: =G16/30 -> 0.48735632 | I16: =VLOOKUP(A16,Classification!$A$2:$F$1180,6,0) -> 298.252 | J16: =-SUM('cons 2023 - 2025'!D17:AM17) -> 31 | K16: =-_xlfn.MINIFS('cons 2023 - 2025'!D17:AM17,'cons 2023 - 2025'!D17:AM17,"<>0") -> 8 | L16: =-_xlfn.MAXIFS('cons 2023 - 2025'!D17:AM17,'cons 2023 - 2025'!D17:AM17,"<>0") -> 1 | M16: =COUNTIF('cons 2023 - 2025'!D17:AM17,"<>0") -> 17 | N16: =-AVERAGE('cons 2023 - 2025'!D17:AM17) -> 0.86111111 | O16: =J16/M16 -> 1.8235294 | P16: =_xlfn.STDEV.S('cons 2023 - 2025'!D17:AM17) -> 1.5334886 | Q16: =-AVERAGE('cons 2023 - 2025'!D17:AM17)/'⚙ Assumptions'!$B$5 -> 0.039141414 | R16: =_xlfn.STDEV.S('cons 2023 - 2025'!D17:AM17)/SQRT('⚙ Assumptions'!$B$5) -> 0.32694087 | S16: =-IF(AVERAGE('cons 2023 - 2025'!D17:AM17)=0,"",_xlfn.STDEV.S('cons 2023 - 2025'!D17:AM17)/AVERAGE('cons 2023 - 2025'!D17:AM17)) -> 1.7808255 | T16: =IF(ISBLANK(S16),"Z", IF(S16<=0.25,"X", IF(S16<=0.5,"Y","Z"))) -> Z | U16: =IF(E16="B",0.95,IF(E16="C",0.9,0.98)) -> 0.95 | V16: =IF(E16="B",1.65,1.28) -> 1.65 | W16: =V16*R16*SQRT(G16) -> 2.0627048 | X16: =V16*P16*SQRT(H16) -> 1.7663949 | Y16: =Q16*G16+W16 -> 2.6349793 | Z16: =N16*H16+X16 -> 2.1860628 | AA16: =-AVERAGE('cons 2023 - 2025'!D17:AM17)*12 -> 10.333333 | AB16: =I16*0.2 -> 59.6504 | AC16: =SQRT((2*AA16*'⚙ Assumptions'!$B$3)/AB16) -> 7.2089857 | AD16: =Z16 -> 2.1860628 | AE16: =Z16+AC16 -> 9.3950486 | AF16: =AA16/AC16 -> 1.4333963
A17: 90250052 | B17: BUSE RINGARDAGE REF:REF B33*1,5 | C17: PC | D17: =VLOOKUP(A17,'Lead Time'!$A$2:$C$1180,3,0) -> Local | E17: =VLOOKUP(A17,Classification!$A$2:$D$1180,4,0) -> B | F17: =VLOOKUP(A17,Classification!$A$2:$E$1180,5,0) -> H | G17: =VLOOKUP(A17,'Lead Time'!$A$2:$D$1180,4,0) -> 36.666667 | H17: =G17/30 -> 1.2222222 | I17: =VLOOKUP(A17,Classification!$A$2:$F$1180,6,0) -> 286.541 | J17: =-SUM('cons 2023 - 2025'!D18:AM18) -> 72 | K17: =-_xlfn.MINIFS('cons 2023 - 2025'!D18:AM18,'cons 2023 - 2025'!D18:AM18,"<>0") -> 9 | L17: =-_xlfn.MAXIFS('cons 2023 - 2025'!D18:AM18,'cons 2023 - 2025'!D18:AM18,"<>0") -> 1 | M17: =COUNTIF('cons 2023 - 2025'!D18:AM18,"<>0") -> 25 | N17: =-AVERAGE('cons 2023 - 2025'!D18:AM18) -> 2 | O17: =J17/M17 -> 2.88 | P17: =_xlfn.STDEV.S('cons 2023 - 2025'!D18:AM18) -> 2.4377976 | Q17: =-AVERAGE('cons 2023 - 2025'!D18:AM18)/'⚙ Assumptions'!$B$5 -> 0.090909091 | R17: =_xlfn.STDEV.S('cons 2023 - 2025'!D18:AM18)/SQRT('⚙ Assumptions'!$B$5) -> 0.51974019 | S17: =-IF(AVERAGE('cons 2023 - 2025'!D18:AM18)=0,"",_xlfn.STDEV.S('cons 2023 - 2025'!D18:AM18)/AVERAGE('cons 2023 - 2025'!D18:AM18)) -> 1.2188988 | T17: =IF(ISBLANK(S17),"Z", IF(S17<=0.25,"X", IF(S17<=0.5,"Y","Z"))) -> Z | U17: =IF(E17="B",0.95,IF(E17="C",0.9,0.98)) -> 0.95 | V17: =IF(E17="B",1.65,1.28) -> 1.65 | W17: =V17*R17*SQRT(G17) -> 5.1928522 | X17: =V17*P17*SQRT(H17) -> 4.446893 | Y17: =Q17*G17+W17 -> 8.5261856 | Z17: =N17*H17+X17 -> 6.8913374 | AA17: =-AVERAGE('cons 2023 - 2025'!D18:AM18)*12 -> 24 | AB17: =I17*0.2 -> 57.3082 | AC17: =SQRT((2*AA17*'⚙ Assumptions'!$B$3)/AB17) -> 11.208768 | AD17: =Z17 -> 6.8913374 | AE17: =Z17+AC17 -> 18.100105 | AF17: =AA17/AC17 -> 2.141181
A18: 83300018 | B18: FILTRE HUILE COMP DSD238 RÉF 6.3465.0 | C18: PC | D18: =VLOOKUP(A18,'Lead Time'!$A$2:$C$1180,3,0) -> Local | E18: =VLOOKUP(A18,Classification!$A$2:$D$1180,4,0) -> B | F18: =VLOOKUP(A18,Classification!$A$2:$E$1180,5,0) -> H | G18: =VLOOKUP(A18,'Lead Time'!$A$2:$D$1180,4,0) -> 11.363636 | H18: =G18/30 -> 0.37878788 | I18: =VLOOKUP(A18,Classification!$A$2:$F$1180,6,0) -> 262.088 | J18: =-SUM('cons 2023 - 2025'!D19:AM19) -> 64 | K18: =-_xlfn.MINIFS('cons 2023 - 2025'!D19:AM19,'cons 2023 - 2025'!D19:AM19,"<>0") -> 7 | L18: =-_xlfn.MAXIFS('cons 2023 - 2025'!D19:AM19,'cons 2023 - 2025'!D19:AM19,"<>0") -> 1 | M18: =COUNTIF('cons 2023 - 2025'!D19:AM19,"<>0") -> 14 | N18: =-AVERAGE('cons 2023 - 2025'!D19:AM19) -> 1.7777778 | O18: =J18/M18 -> 4.5714286 | P18: =_xlfn.STDEV.S('cons 2023 - 2025'!D19:AM19) -> 2.5979235 | Q18: =-AVERAGE('cons 2023 - 2025'!D19:AM19)/'⚙ Assumptions'!$B$5 -> 0.080808081 | R18: =_xlfn.STDEV.S('cons 2023 - 2025'!D19:AM19)/SQRT('⚙ Assumptions'!$B$5) -> 0.55387914 | S18: =-IF(AVERAGE('cons 2023 - 2025'!D19:AM19)=0,"",_xlfn.STDEV.S('cons 2023 - 2025'!D19:AM19)/AVERAGE('cons 2023 - 2025'!D19:AM19)) -> 1.461332 | T18: =IF(ISBLANK(S18),"Z", IF(S18<=0.25,"X", IF(S18<=0.5,"Y","Z"))) -> Z | U18: =IF(E18="B",0.95,IF(E18="C",0.9,0.98)) -> 0.95 | V18: =IF(E18="B",1.65,1.28) -> 1.65 | W18: =V18*R18*SQRT(G18) -> 3.0807583 | X18: =V18*P18*SQRT(H18) -> 2.6382038 | Y18: =Q18*G18+W18 -> 3.9990319 | Z18: =N18*H18+X18 -> 3.3116044 | AA18: =-AVERAGE('cons 2023 - 2025'!D19:AM19)*12 -> 21.333333 | AB18: =I18*0.2 -> 52.4176 | AC18: =SQRT((2*AA18*'⚙ Assumptions'!$B$3)/AB18) -> 11.049724 | AD18: =Z18 -> 3.3116044 | AE18: =Z18+AC18 -> 14.361328 | AF18: =AA18/AC18 -> 1.9306667
A19: 43200054 | B19: Electrode OK 67.45 E307 3.2mm | C19: PAQ | D19: =VLOOKUP(A19,'Lead Time'!$A$2:$C$1180,3,0) -> Local | E19: =VLOOKUP(A19,Classification!$A$2:$D$1180,4,0) -> B | F19: =VLOOKUP(A19,Classification!$A$2:$E$1180,5,0) -> H | G19: =VLOOKUP(A19,'Lead Time'!$A$2:$D$1180,4,0) -> 13.125 | H19: =G19/30 -> 0.4375 | I19: =VLOOKUP(A19,Classification!$A$2:$F$1180,6,0) -> 249.277 | J19: =-SUM('cons 2023 - 2025'!D20:AM20) -> 53 | K19: =-_xlfn.MINIFS('cons 2023 - 2025'!D20:AM20,'cons 2023 - 2025'!D20:AM20,"<>0") -> 21 | L19: =-_xlfn.MAXIFS('cons 2023 - 2025'!D20:AM20,'cons 2023 - 2025'!D20:AM20,"<>0") -> 1 | M19: =COUNTIF('cons 2023 - 2025'!D20:AM20,"<>0") -> 8 | N19: =-AVERAGE('cons 2023 - 2025'!D20:AM20) -> 1.4722222 | O19: =J19/M19 -> 6.625 | P19: =_xlfn.STDEV.S('cons 2023 - 2025'!D20:AM20) -> 4.3259094 | Q19: =-AVERAGE('cons 2023 - 2025'!D20:AM20)/'⚙ Assumptions'!$B$5 -> 0.066919192 | R19: =_xlfn.STDEV.S('cons 2023 - 2025'!D20:AM20)/SQRT('⚙ Assumptions'!$B$5) -> 0.92228698 | S19: =-IF(AVERAGE('cons 2023 - 2025'!D20:AM20)=0,"",_xlfn.STDEV.S('cons 2023 - 2025'!D20:AM20)/AVERAGE('cons 2023 - 2025'!D20:AM20)) -> 2.9383535 | T19: =IF(ISBLANK(S19),"Z", IF(S19<=0.25,"X", IF(S19<=0.5,"Y","Z"))) -> Z | U19: =IF(E19="B",0.95,IF(E19="C",0.9,0.98)) -> 0.95 | V19: =IF(E19="B",1.65,1.28) -> 1.65 | W19: =V19*R19*SQRT(G19) -> 5.5131483 | X19: =V19*P19*SQRT(H19) -> 4.7211782 | Y19: =Q19*G19+W19 -> 6.3914627 | Z19: =N19*H19+X19 -> 5.3652754 | AA19: =-AVERAGE('cons 2023 - 2025'!D20:AM20)*12 -> 17.666667 | AB19: =I19*0.2 -> 49.8554 | AC19: =SQRT((2*AA19*'⚙ Assumptions'!$B$3)/AB19) -> 10.31055 | AD19: =Z19 -> 5.3652754 | AE19: =Z19+AC19 -> 15.675825 | AF19: =AA19/AC19 -> 1.7134553
A20: 59050017 | B20: DETECTEUR *IGM200 | C20: PC | D20: =VLOOKUP(A20,'Lead Time'!$A$2:$C$1180,3,0) -> Local | E20: =VLOOKUP(A20,Classification!$A$2:$D$1180,4,0) -> B | F20: =VLOOKUP(A20,Classification!$A$2:$E$1180,5,0) -> H | G20: =VLOOKUP(A20,'Lead Time'!$A$2:$D$1180,4,0) -> 86.2 | H20: =G20/30 -> 2.8733333 | I20: =VLOOKUP(A20,Classification!$A$2:$F$1180,6,0) -> 245.543 | J20: =-SUM('cons 2023 - 2025'!D21:AM21) -> 33 | K20: =-_xlfn.MINIFS('cons 2023 - 2025'!D21:AM21,'cons 2023 - 2025'!D21:AM21,"<>0") -> 5 | L20: =-_xlfn.MAXIFS('cons 2023 - 2025'!D21:AM21,'cons 2023 - 2025'!D21:AM21,"<>0") -> 1 | M20: =COUNTIF('cons 2023 - 2025'!D21:AM21,"<>0") -> 15 | N20: =-AVERAGE('cons 2023 - 2025'!D21:AM21) -> 0.91666667 | O20: =J20/M20 -> 2.2 | P20: =_xlfn.STDEV.S('cons 2023 - 2025'!D21:AM21) -> 1.3174651 | Q20: =-AVERAGE('cons 2023 - 2025'!D21:AM21)/'⚙ Assumptions'!$B$5 -> 0.041666667 | R20: =_xlfn.STDEV.S('cons 2023 - 2025'!D21:AM21)/SQRT('⚙ Assumptions'!$B$5) -> 0.2808845 | S20: =-IF(AVERAGE('cons 2023 - 2025'!D21:AM21)=0,"",_xlfn.STDEV.S('cons 2023 - 2025'!D21:AM21)/AVERAGE('cons 2023 - 2025'!D21:AM21)) -> 1.4372347 | T20: =IF(ISBLANK(S20),"Z", IF(S20<=0.25,"X", IF(S20<=0.5,"Y","Z"))) -> Z | U20: =IF(E20="B",0.95,IF(E20="C",0.9,0.98)) -> 0.95 | V20: =IF(E20="B",1.65,1.28) -> 1.65 | W20: =V20*R20*SQRT(G20) -> 4.3029406 | X20: =V20*P20*SQRT(H20) -> 3.6848182 | Y20: =Q20*G20+W20 -> 7.8946073 | Z20: =N20*H20+X20 -> 6.3187071 | AA20: =-AVERAGE('cons 2023 - 2025'!D21:AM21)*12 -> 11 | AB20: =I20*0.2 -> 49.1086 | AC20: =SQRT((2*AA20*'⚙ Assumptions'!$B$3)/AB20) -> 8.197439 | AD20: =Z20 -> 6.3187071 | AE20: =Z20+AC20 -> 14.516146 | AF20: =AA20/AC20 -> 1.3418825
... A36: 91100459 | B36: SELLE DROITE | C36: PC | D36: =VLOOKUP(A36,'Lead Time'!$A$2:$C$1180,3,0) -> Local | E36: =VLOOKUP(A36,Classification!$A$2:$D$1180,4,0) -> C | F36: =VLOOKUP(A36,Classification!$A$2:$E$1180,5,0) -> M | G36: =VLOOKUP(A36,'Lead Time'!$A$2:$D$1180,4,0) -> 171.5 | H36: =G36/30 -> 5.7166667 | I36: =VLOOKUP(A36,Classification!$A$2:$F$1180,6,0) -> 148.745 | J36: =-SUM('cons 2023 - 2025'!D37:AM37) -> 12 | K36: =-_xlfn.MINIFS('cons 2023 - 2025'!D37:AM37,'cons 2023 - 2025'!D37:AM37,"<>0") -> 3 | L36: =-_xlfn.MAXIFS('cons 2023 - 2025'!D37:AM37,'cons 2023 - 2025'!D37:AM37,"<>0") -> 2 | M36: =COUNTIF('cons 2023 - 2025'!D37:AM37,"<>0") -> 5 | N36: =-AVERAGE('cons 2023 - 2025'!D37:AM37) -> 0.33333333 | O36: =J36/M36 -> 2.4 | P36: =_xlfn.STDEV.S('cons 2023 - 2025'!D37:AM37) -> 0.86189161 | Q36: =-AVERAGE('cons 2023 - 2025'!D37:AM37)/'⚙ Assumptions'!$B$5 -> 0.015151515 | R36: =_xlfn.STDEV.S('cons 2023 - 2025'!D37:AM37)/SQRT('⚙ Assumptions'!$B$5) -> 0.18375591 | S36: =-IF(AVERAGE('cons 2023 - 2025'!D37:AM37)=0,"",_xlfn.STDEV.S('cons 2023 - 2025'!D37:AM37)/AVERAGE('cons 2023 - 2025'!D37:AM37)) -> 2.5856748 | T36: =IF(ISBLANK(S36),"Z", IF(S36<=0.25,"X", IF(S36<=0.5,"Y","Z"))) -> Z | U36: =IF(E36="B",0.95,IF(E36="C",0.9,0.98)) -> 0.9 | V36: =IF(E36="B",1.65,1.28) -> 1.28 | W36: =V36*R36*SQRT(G36) -> 3.0802314 | X36: =V36*P36*SQRT(H36) -> 2.6377526 | Y36: =Q36*G36+W36 -> 5.6787162 | Z36: =N36*H36+X36 -> 4.5433081 | AA36: =-AVERAGE('cons 2023 - 2025'!D37:AM37)*12 -> 4 | AB36: =I36*0.2 -> 29.749 | AC36: =SQRT((2*AA36*'⚙ Assumptions'!$B$3)/AB36) -> 6.3511802 | AD36: =Z36 -> 4.5433081 | AE36: =Z36+AC36 -> 10.894488 | AF36: =AA36/AC36 -> 0.6298042
A37: 02030003 | B37: CEMI HRS SAC | C37: TO | E37: =VLOOKUP(A37,Classification!$A$2:$D$1180,4,0) -> C | F37: =VLOOKUP(A37,Classification!$A$2:$E$1180,5,0) -> H | G37: =VLOOKUP(A37,'Lead Time'!$A$2:$D$1180,4,0) -> 44 | H37: =G37/30 -> 1.4666667 | I37: =VLOOKUP(A37,Classification!$A$2:$F$1180,6,0) -> 147.905 | J37: =-SUM('cons 2023 - 2025'!D38:AM38) -> 208664.9 | K37: =-_xlfn.MINIFS('cons 2023 - 2025'!D38:AM38,'cons 2023 - 2025'!D38:AM38,"<>0") -> 59802.85 | L37: =-_xlfn.MAXIFS('cons 2023 - 2025'!D38:AM38,'cons 2023 - 2025'!D38:AM38,"<>0") -> 637.6 | M37: =COUNTIF('cons 2023 - 2025'!D38:AM38,"<>0") -> 36 | N37: =-AVERAGE('cons 2023 - 2025'!D38:AM38) -> 5796.2472 | O37: =J37/M37 -> 5796.2472 | P37: =_xlfn.STDEV.S('cons 2023 - 2025'!D38:AM38) -> 9368.3708 | Q37: =-AVERAGE('cons 2023 - 2025'!D38:AM38)/'⚙ Assumptions'!$B$5 -> 263.46578 | R37: =_xlfn.STDEV.S('cons 2023 - 2025'!D38:AM38)/SQRT('⚙ Assumptions'!$B$5) -> 1997.3434 | S37: =-IF(AVERAGE('cons 2023 - 2025'!D38:AM38)=0,"",_xlfn.STDEV.S('cons 2023 - 2025'!D38:AM38)/AVERAGE('cons 2023 - 2025'!D38:AM38)) -> 1.6162821 | T37: =IF(ISBLANK(S37),"Z", IF(S37<=0.25,"X", IF(S37<=0.5,"Y","Z"))) -> Z | U37: =IF(E37="B",0.95,IF(E37="C",0.9,0.98)) -> 0.9 | V37: =IF(E37="B",1.65,1.28) -> 1.28 | W37: =V37*R37*SQRT(G37) -> 16958.563 | X37: =V37*P37*SQRT(H37) -> 14522.445 | Y37: =Q37*G37+W37 -> 28551.057 | Z37: =N37*H37+X37 -> 23023.608 | AA37: =-AVERAGE('cons 2023 - 2025'!D38:AM38)*12 -> 69554.967 | AB37: =I37*0.2 -> 29.581 | AC37: =SQRT((2*AA37*'⚙ Assumptions'!$B$3)/AB37) -> 839.882 | AD37: =Z37 -> 23023.608 | AE37: =Z37+AC37 -> 23863.49 | AF37: =AA37/AC37 -> 82.815165
A38: 53250184 | B38: Relais thermique 23-32A LRD332 | C38: PC | D38: =VLOOKUP(A38,'Lead Time'!$A$2:$C$1180,3,0) -> Local | E38: =VLOOKUP(A38,Classification!$A$2:$D$1180,4,0) -> C | F38: =VLOOKUP(A38,Classification!$A$2:$E$1180,5,0) -> L | G38: =VLOOKUP(A38,'Lead Time'!$A$2:$D$1180,4,0) -> 99 | H38: =G38/30 -> 3.3 | I38: =VLOOKUP(A38,Classification!$A$2:$F$1180,6,0) -> 147.497 | J38: =-SUM('cons 2023 - 2025'!D39:AM39) -> 4 | K38: =-_xlfn.MINIFS('cons 2023 - 2025'!D39:AM39,'cons 2023 - 2025'!D39:AM39,"<>0") -> 2 | L38: =-_xlfn.MAXIFS('cons 2023 - 2025'!D39:AM39,'cons 2023 - 2025'!D39:AM39,"<>0") -> 1 | M38: =COUNTIF('cons 2023 - 2025'!D39:AM39,"<>0") -> 3 | N38: =-AVERAGE('cons 2023 - 2025'!D39:AM39) -> 0.11111111 | O38: =J38/M38 -> 1.3333333 | P38: =_xlfn.STDEV.S('cons 2023 - 2025'!D39:AM39) -> 0.39840954 | Q38: =-AVERAGE('cons 2023 - 2025'!D39:AM39)/'⚙ Assumptions'!$B$5 -> 0.0050505051 | R38: =_xlfn.STDEV.S('cons 2023 - 2025'!D39:AM39)/SQRT('⚙ Assumptions'!$B$5) -> 0.084941199 | S38: =-IF(AVERAGE('cons 2023 - 2025'!D39:AM39)=0,"",_xlfn.STDEV.S('cons 2023 - 2025'!D39:AM39)/AVERAGE('cons 2023 - 2025'!D39:AM39)) -> 3.5856858 | T38: =IF(ISBLANK(S38),"Z", IF(S38<=0.25,"X", IF(S38<=0.5,"Y","Z"))) -> Z | U38: =IF(E38="B",0.95,IF(E38="C",0.9,0.98)) -> 0.9 | V38: =IF(E38="B",1.65,1.28) -> 1.28 | W38: =V38*R38*SQRT(G38) -> 1.0817974 | X38: =V38*P38*SQRT(H38) -> 0.92639599 | Y38: =Q38*G38+W38 -> 1.5817974 | Z38: =N38*H38+X38 -> 1.2930627 | AA38: =-AVERAGE('cons 2023 - 2025'!D39:AM39)*12 -> 1.3333333 | AB38: =I38*0.2 -> 29.4994 | AC38: =SQRT((2*AA38*'⚙ Assumptions'!$B$3)/AB38) -> 3.6823359 | AD38: =Z38 -> 1.2930627 | AE38: =Z38+AC38 -> 4.9753986 | AF38: =AA38/AC38 -> 0.362089
A39: 10030103 | B39: BRIQUE MLA RP201 KROSAKI | C39: PC | E39: =VLOOKUP(A39,Classification!$A$2:$D$1180,4,0) -> C | F39: =VLOOKUP(A39,Classification!$A$2:$E$1180,5,0) -> L | G39: =VLOOKUP(A39,'Lead Time'!$A$2:$D$1180,4,0) -> 0 | H39: =G39/30 -> 0 | I39: =VLOOKUP(A39,Classification!$A$2:$F$1180,6,0) -> 147.278 | J39: =-SUM('cons 2023 - 2025'!D40:AM40) -> 2 | K39: =-_xlfn.MINIFS('cons 2023 - 2025'!D40:AM40,'cons 2023 - 2025'!D40:AM40,"<>0") -> 2 | L39: =-_xlfn.MAXIFS('cons 2023 - 2025'!D40:AM40,'cons 2023 - 2025'!D40:AM40,"<>0") -> 2 | M39: =COUNTIF('cons 2023 - 2025'!D40:AM40,"<>0") -> 1 | N39: =-AVERAGE('cons 2023 - 2025'!D40:AM40) -> 0.055555556 | O39: =J39/M39 -> 2 | P39: =_xlfn.STDEV.S('cons 2023 - 2025'!D40:AM40) -> 0.33333333 | Q39: =-AVERAGE('cons 2023 - 2025'!D40:AM40)/'⚙ Assumptions'!$B$5 -> 0.0025252525 | R39: =_xlfn.STDEV.S('cons 2023 - 2025'!D40:AM40)/SQRT('⚙ Assumptions'!$B$5) -> 0.071066905 | S39: =-IF(AVERAGE('cons 2023 - 2025'!D40:AM40)=0,"",_xlfn.STDEV.S('cons 2023 - 2025'!D40:AM40)/AVERAGE('cons 2023 - 2025'!D40:AM40)) -> 6 | T39: =IF(ISBLANK(S39),"Z", IF(S39<=0.25,"X", IF(S39<=0.5,"Y","Z"))) -> Z | U39: =IF(E39="B",0.95,IF(E39="C",0.9,0.98)) -> 0.9 | V39: =IF(E39="B",1.65,1.28) -> 1.28 | W39: =V39*R39*SQRT(G39) -> 0 | X39: =V39*P39*SQRT(H39) -> 0 | Y39: =Q39*G39+W39 -> 0 | Z39: =N39*H39+X39 -> 0 | AA39: =-AVERAGE('cons 2023 - 2025'!D40:AM40)*12 -> 0.66666667 | AB39: =I39*0.2 -> 29.4556 | AC39: =SQRT((2*AA39*'⚙ Assumptions'!$B$3)/AB39) -> 2.6057399 | AD39: =Z39 -> 0 | AE39: =Z39+AC39 -> 2.6057399 | AF39: =AA39/AC39 -> 0.25584544
A40: 20300015 | B40: FER PLAT 100*8 LONG 6M | C40: PC | D40: =VLOOKUP(A40,'Lead Time'!$A$2:$C$1180,3,0) -> Local | E40: =VLOOKUP(A40,Classification!$A$2:$D$1180,4,0) -> C | F40: =VLOOKUP(A40,Classification!$A$2:$E$1180,5,0) -> M | G40: =VLOOKUP(A40,'Lead Time'!$A$2:$D$1180,4,0) -> 36 | H40: =G40/30 -> 1.2 | I40: =VLOOKUP(A40,Classification!$A$2:$F$1180,6,0) -> 147.058 | J40: =-SUM('cons 2023 - 2025'!D41:AM41) -> 10 | K40: =-_xlfn.MINIFS('cons 2023 - 2025'!D41:AM41,'cons 2023 - 2025'!D41:AM41,"<>0") -> 2 | L40: =-_xlfn.MAXIFS('cons 2023 - 2025'!D41:AM41,'cons 2023 - 2025'!D41:AM41,"<>0") -> 1 | M40: =COUNTIF('cons 2023 - 2025'!D41:AM41,"<>0") -> 8 | N40: =-AVERAGE('cons 2023 - 2025'!D41:AM41) -> 0.27777778 | O40: =J40/M40 -> 1.25 | P40: =_xlfn.STDEV.S('cons 2023 - 2025'!D41:AM41) -> 0.56624634 | Q40: =-AVERAGE('cons 2023 - 2025'!D41:AM41)/'⚙ Assumptions'!$B$5 -> 0.012626263 | R40: =_xlfn.STDEV.S('cons 2023 - 2025'!D41:AM41)/SQRT('⚙ Assumptions'!$B$5) -> 0.12072413 | S40: =-IF(AVERAGE('cons 2023 - 2025'!D41:AM41)=0,"",_xlfn.STDEV.S('cons 2023 - 2025'!D41:AM41)/AVERAGE('cons 2023 - 2025'!D41:AM41)) -> 2.0384868 | T40: =IF(ISBLANK(S40),"Z", IF(S40<=0.25,"X", IF(S40<=0.5,"Y","Z"))) -> Z | U40: =IF(E40="B",0.95,IF(E40="C",0.9,0.98)) -> 0.9 | V40: =IF(E40="B",1.65,1.28) -> 1.28 | W40: =V40*R40*SQRT(G40) -> 0.92716129 | X40: =V40*P40*SQRT(H40) -> 0.79397349 | Y40: =Q40*G40+W40 -> 1.3817067 | Z40: =N40*H40+X40 -> 1.1273068 | AA40: =-AVERAGE('cons 2023 - 2025'!D41:AM41)*12 -> 3.3333333 | AB40: =I40*0.2 -> 29.4116 | AC40: =SQRT((2*AA40*'⚙ Assumptions'!$B$3)/AB40) -> 5.8309682 | AD40: =Z40 -> 1.1273068 | AE40: =Z40+AC40 -> 6.958275 | AF40: =AA40/AC40 -> 0.57166035
A41: 20030006 | B41: POUTREL EN ACIER UPN80 (6m) | C41: PC | D41: =VLOOKUP(A41,'Lead Time'!$A$2:$C$1180,3,0) -> Local | E41: =VLOOKUP(A41,Classification!$A$2:$D$1180,4,0) -> C | F41: =VLOOKUP(A41,Classification!$A$2:$E$1180,5,0) -> L | G41: =VLOOKUP(A41,'Lead Time'!$A$2:$D$1180,4,0) -> 17.9 | H41: =G41/30 -> 0.59666667 | I41: =VLOOKUP(A41,Classification!$A$2:$F$1180,6,0) -> 146.908 | J41: =-SUM('cons 2023 - 2025'!D42:AM42) -> 11 | K41: =-_xlfn.MINIFS('cons 2023 - 2025'!D42:AM42,'cons 2023 - 2025'!D42:AM42,"<>0") -> 2 | L41: =-_xlfn.MAXIFS('cons 2023 - 2025'!D42:AM42,'cons 2023 - 2025'!D42:AM42,"<>0") -> 1 | M41: =COUNTIF('cons 2023 - 2025'!D42:AM42,"<>0") -> 8 | N41: =-AVERAGE('cons 2023 - 2025'!D42:AM42) -> 0.30555556 | O41: =J41/M41 -> 1.375 | P41: =_xlfn.STDEV.S('cons 2023 - 2025'!D42:AM42) -> 0.62424558 | Q41: =-AVERAGE('cons 2023 - 2025'!D42:AM42)/'⚙ Assumptions'!$B$5 -> 0.013888889 | R41: =_xlfn.STDEV.S('cons 2023 - 2025'!D42:AM42)/SQRT('⚙ Assumptions'!$B$5) -> 0.1330896 | S41: =-IF(AVERAGE('cons 2023 - 2025'!D42:AM42)=0,"",_xlfn.STDEV.S('cons 2023 - 2025'!D42:AM42)/AVERAGE('cons 2023 - 2025'!D42:AM42)) -> 2.0429855 | T41: =IF(ISBLANK(S41),"Z", IF(S41<=0.25,"X", IF(S41<=0.5,"Y","Z"))) -> Z | U41: =IF(E41="B",0.95,IF(E41="C",0.9,0.98)) -> 0.9 | V41: =IF(E41="B",1.65,1.28) -> 1.28 | W41: =V41*R41*SQRT(G41) -> 0.72074331 | X41: =V41*P41*SQRT(H41) -> 0.61720769 | Y41: =Q41*G41+W41 -> 0.96935442 | Z41: =N41*H41+X41 -> 0.79952251 | AA41: =-AVERAGE('cons 2023 - 2025'!D42:AM42)*12 -> 3.6666667 | AB41: =I41*0.2 -> 29.3816 | AC41: =SQRT((2*AA41*'⚙ Assumptions'!$B$3)/AB41) -> 6.1186924 | AD41: =Z41 -> 0.79952251 | AE41: =Z41+AC41 -> 6.9182149 | AF41: =AA41/AC41 -> 0.59925658
A42: 83300017 | B42: FILTRE HUILE COMP ASD57 REF 6.3463.0 | C42: PC | D42: =VLOOKUP(A42,'Lead Time'!$A$2:$C$1180,3,0) -> Local | E42: =VLOOKUP(A42,Classification!$A$2:$D$1180,4,0) -> C | F42: =VLOOKUP(A42,Classification!$A$2:$E$1180,5,0) -> L | G42: =VLOOKUP(A42,'Lead Time'!$A$2:$D$1180,4,0) -> 58.75 | H42: =G42/30 -> 1.9583333 | I42: =VLOOKUP(A42,Classification!$A$2:$F$1180,6,0) -> 146.688 | J42: =-SUM('cons 2023 - 2025'!D43:AM43) -> 3 | K42: =-_xlfn.MINIFS('cons 2023 - 2025'!D43:AM43,'cons 2023 - 2025'!D43:AM43,"<>0") -> 1 | L42: =-_xlfn.MAXIFS('cons 2023 - 2025'!D43:AM43,'cons 2023 - 2025'!D43:AM43,"<>0") -> 1 | M42: =COUNTIF('cons 2023 - 2025'!D43:AM43,"<>0") -> 3 | N42: =-AVERAGE('cons 2023 - 2025'!D43:AM43) -> 0.083333333 | O42: =J42/M42 -> 1 | P42: =_xlfn.STDEV.S('cons 2023 - 2025'!D43:AM43) -> 0.28030596 | Q42: =-AVERAGE('cons 2023 - 2025'!D43:AM43)/'⚙ Assumptions'!$B$5 -> 0.0037878788 | R42: =_xlfn.STDEV.S('cons 2023 - 2025'!D43:AM43)/SQRT('⚙ Assumptions'!$B$5) -> 0.05976143 | S42: =-IF(AVERAGE('cons 2023 - 2025'!D43:AM43)=0,"",_xlfn.STDEV.S('cons 2023 - 2025'!D43:AM43)/AVERAGE('cons 2023 - 2025'!D43:AM43)) -> 3.3636715 | T42: =IF(ISBLANK(S42),"Z", IF(S42<=0.25,"X", IF(S42<=0.5,"Y","Z"))) -> Z | U42: =IF(E42="B",0.95,IF(E42="C",0.9,0.98)) -> 0.9 | V42: =IF(E42="B",1.65,1.28) -> 1.28 | W42: =V42*R42*SQRT(G42) -> 0.58632024 | X42: =V42*P42*SQRT(H42) -> 0.50209466 | Y42: =Q42*G42+W42 -> 0.80885812 | Z42: =N42*H42+X42 -> 0.6652891 | AA42: =-AVERAGE('cons 2023 - 2025'!D43:AM43)*12 -> 1 | AB42: =I42*0.2 -> 29.3376 | AC42: =SQRT((2*AA42*'⚙ Assumptions'!$B$3)/AB42) -> 3.1977782 | AD42: =Z42 -> 0.6652891 | AE42: =Z42+AC42 -> 3.8630673 | AF42: =AA42/AC42 -> 0.31271712
A43: 84100979 | B43: Cale 1 (100*100) TMAS 100-100 | C43: PC | D43: =VLOOKUP(A43,'Lead Time'!$A$2:$C$1180,3,0) -> Local | E43: =VLOOKUP(A43,Classification!$A$2:$D$1180,4,0) -> C | F43: =VLOOKUP(A43,Classification!$A$2:$E$1180,5,0) -> M | G43: =VLOOKUP(A43,'Lead Time'!$A$2:$D$1180,4,0) -> 76 | H43: =G43/30 -> 2.5333333 | I43: =VLOOKUP(A43,Classification!$A$2:$F$1180,6,0) -> 146.502 | J43: =-SUM('cons 2023 - 2025'!D44:AM44) -> 20 | K43: =-_xlfn.MINIFS('cons 2023 - 2025'!D44:AM44,'cons 2023 - 2025'!D44:AM44,"<>0") -> 10 | L43: =-_xlfn.MAXIFS('cons 2023 - 2025'!D44:AM44,'cons 2023 - 2025'!D44:AM44,"<>0") -> 1 | M43: =COUNTIF('cons 2023 - 2025'!D44:AM44,"<>0") -> 4 | N43: =-AVERAGE('cons 2023 - 2025'!D44:AM44) -> 0.55555556 | O43: =J43/M43 -> 5 | P43: =_xlfn.STDEV.S('cons 2023 - 2025'!D44:AM44) -> 1.9631526 | Q43: =-AVERAGE('cons 2023 - 2025'!D44:AM44)/'⚙ Assumptions'!$B$5 -> 0.025252525 | R43: =_xlfn.STDEV.S('cons 2023 - 2025'!D44:AM44)/SQRT('⚙ Assumptions'!$B$5) -> 0.41854555 | S43: =-IF(AVERAGE('cons 2023 - 2025'!D44:AM44)=0,"",_xlfn.STDEV.S('cons 2023 - 2025'!D44:AM44)/AVERAGE('cons 2023 - 2025'!D44:AM44)) -> 3.5336747 | T43: =IF(ISBLANK(S43),"Z", IF(S43<=0.25,"X", IF(S43<=0.5,"Y","Z"))) -> Z | U43: =IF(E43="B",0.95,IF(E43="C",0.9,0.98)) -> 0.9 | V43: =IF(E43="B",1.65,1.28) -> 1.28 | W43: =V43*R43*SQRT(G43) -> 4.6704582 | X43: =V43*P43*SQRT(H43) -> 3.9995415 | Y43: =Q43*G43+W43 -> 6.5896501 | Z43: =N43*H43+X43 -> 5.4069489 | AA43: =-AVERAGE('cons 2023 - 2025'!D44:AM44)*12 -> 6.6666667 | AB43: =I43*0.2 -> 29.3004 | AC43: =SQRT((2*AA43*'⚙ Assumptions'!$B$3)/AB43) -> 8.2618675 | AD43: =Z43 -> 5.4069489 | AE43: =Z43+AC43 -> 13.668816 | AF43: =AA43/AC43 -> 0.80692007
A44: 90250019 | B44: RONDELLE BASSE rep1268 | C44: PC | D44: =VLOOKUP(A44,'Lead Time'!$A$2:$C$1180,3,0) -> Mixed Source | E44: =VLOOKUP(A44,Classification!$A$2:$D$1180,4,0) -> C | F44: =VLOOKUP(A44,Classification!$A$2:$E$1180,5,0) -> M | G44: =VLOOKUP(A44,'Lead Time'!$A$2:$D$1180,4,0) -> 25.846154 | H44: =G44/30 -> 0.86153846 | I44: =VLOOKUP(A44,Classification!$A$2:$F$1180,6,0) -> 145.83 | J44: =-SUM('cons 2023 - 2025'!D45:AM45) -> 18 | K44: =-_xlfn.MINIFS('cons 2023 - 2025'!D45:AM45,'cons 2023 - 2025'!D45:AM45,"<>0") -> 3 | L44: =-_xlfn.MAXIFS('cons 2023 - 2025'!D45:AM45,'cons 2023 - 2025'!D45:AM45,"<>0") -> 3 | M44: =COUNTIF('cons 2023 - 2025'!D45:AM45,"<>0") -> 6 | N44: =-AVERAGE('cons 2023 - 2025'!D45:AM45) -> 0.5 | O44: =J44/M44 -> 3 | P44: =_xlfn.STDEV.S('cons 2023 - 2025'!D45:AM45) -> 1.1338934 | Q44: =-AVERAGE('cons 2023 - 2025'!D45:AM45)/'⚙ Assumptions'!$B$5 -> 0.022727273 | R44: =_xlfn.STDEV.S('cons 2023 - 2025'!D45:AM45)/SQRT('⚙ Assumptions'!$B$5) -> 0.24174689 | S44: =-IF(AVERAGE('cons 2023 - 2025'!D45:AM45)=0,"",_xlfn.STDEV.S('cons 2023 - 2025'!D45:AM45)/AVERAGE('cons 2023 - 2025'!D45:AM45)) -> 2.2677868 | T44: =IF(ISBLANK(S44),"Z", IF(S44<=0.25,"X", IF(S44<=0.5,"Y","Z"))) -> Z | U44: =IF(E44="B",0.95,IF(E44="C",0.9,0.98)) -> 0.9 | V44: =IF(E44="B",1.65,1.28) -> 1.28 | W44: =V44*R44*SQRT(G44) -> 1.5731453 | X44: =V44*P44*SQRT(H44) -> 1.3471611 | Y44: =Q44*G44+W44 -> 2.1605578 | Z44: =N44*H44+X44 -> 1.7779303 | AA44: =-AVERAGE('cons 2023 - 2025'!D45:AM45)*12 -> 6 | AB44: =I44*0.2 -> 29.166 | AC44: =SQRT((2*AA44*'⚙ Assumptions'!$B$3)/AB44) -> 7.8559338 | AD44: =Z44 -> 1.7779303 | AE44: =Z44+AC44 -> 9.6338642 | AF44: =AA44/AC44 -> 0.76375389
A45: 20010002 | B45: POUTRE IPN 100 6M | C45: PC | D45: =VLOOKUP(A45,'Lead Time'!$A$2:$C$1180,3,0) -> Local | E45: =VLOOKUP(A45,Classification!$A$2:$D$1180,4,0) -> C | F45: =VLOOKUP(A45,Classification!$A$2:$E$1180,5,0) -> M | G45: =VLOOKUP(A45,'Lead Time'!$A$2:$D$1180,4,0) -> 12.2 | H45: =G45/30 -> 0.40666667 | I45: =VLOOKUP(A45,Classification!$A$2:$F$1180,6,0) -> 144.537 | J45: =-SUM('cons 2023 - 2025'!D46:AM46) -> 9 | K45: =-_xlfn.MINIFS('cons 2023 - 2025'!D46:AM46,'cons 2023 - 2025'!D46:AM46,"<>0") -> 4 | L45: =-_xlfn.MAXIFS('cons 2023 - 2025'!D46:AM46,'cons 2023 - 2025'!D46:AM46,"<>0") -> 1 | M45: =COUNTIF('cons 2023 - 2025'!D46:AM46,"<>0") -> 5 | N45: =-AVERAGE('cons 2023 - 2025'!D46:AM46) -> 0.25 | O45: =J45/M45 -> 1.8 | P45: =_xlfn.STDEV.S('cons 2023 - 2025'!D46:AM46) -> 0.76997217 | Q45: =-AVERAGE('cons 2023 - 2025'!D46:AM46)/'⚙ Assumptions'!$B$5 -> 0.011363636 | R45: =_xlfn.STDEV.S('cons 2023 - 2025'!D46:AM46)/SQRT('⚙ Assumptions'!$B$5) -> 0.16415862 | S45: =-IF(AVERAGE('cons 2023 - 2025'!D46:AM46)=0,"",_xlfn.STDEV.S('cons 2023 - 2025'!D46:AM46)/AVERAGE('cons 2023 - 2025'!D46:AM46)) -> 3.0798887 | T45: =IF(ISBLANK(S45),"Z", IF(S45<=0.25,"X", IF(S45<=0.5,"Y","Z"))) -> Z | U45: =IF(E45="B",0.95,IF(E45="C",0.9,0.98)) -> 0.9 | V45: =IF(E45="B",1.65,1.28) -> 1.28 | W45: =V45*R45*SQRT(G45) -> 0.7339282 | X45: =V45*P45*SQRT(H45) -> 0.62849856 | Y45: =Q45*G45+W45 -> 0.87256456 | Z45: =N45*H45+X45 -> 0.73016523 | AA45: =-AVERAGE('cons 2023 - 2025'!D46:AM46)*12 -> 3 | AB45: =I45*0.2 -> 28.9074 | AC45: =SQRT((2*AA45*'⚙ Assumptions'!$B$3)/AB45) -> 5.5797757 | AD45: =Z45 -> 0.73016523 | AE45: =Z45+AC45 -> 6.3099409 | AF45: =AA45/AC45 -> 0.53765602
